Workbook
Name \0: #N/A
Name \a: #REF!
Name \c: #REF!
Name \p: #REF!
Name \q: [1]FRYPROD!#REF!
Name ___RSE2: '[2]CMA Calculations'!$H$1066
Name __DAT1: "$#REF!.$A$1:$A$394"
Name __DAT10: #REF!
Name __DAT11: #REF!
Name __DAT12: #REF!
Name __DAT13: #REF!
Name __DAT14: #REF!
Name __DAT15: #REF!
Name __DAT16: #REF!
Name __DAT2: "$#REF!.$B$1:$B$394"
Name __DAT3: "$#REF!.$#REF!$#REF!:$#REF!$#REF!"
Name __DAT6: #REF!
Name __DAT7: #REF!
Name __DAT8: #REF!
Name __DAT9: #REF!
Name __NPW1: '[3]Permanent info'!$E$5
Name __NPW10: '[3]Permanent info'!$R$5
Name __NPW11: '[3]Permanent info'!$S$5
Name __NPW2: '[3]Permanent info'!$G$5
Name __NPW3: '[3]Permanent info'!$H$5
Name __NPW4: '[3]Permanent info'!$I$5
Name __NPW5: '[3]Permanent info'!$K$5
Name __NPW6: '[3]Permanent info'!$L$5
Name __NPW7: '[3]Permanent info'!$M$5
Name __NPW8: '[3]Permanent info'!$O$5
Name __NPW9: '[3]Permanent info'!$Q$5
Name __poc01: #REF!
Name __poc02: #REF!
Name __poc03: #REF!
Name __poc04: #REF!
Name __poc05: #REF!
Name __PPH25: #REF!
Name __RSE2: '[2]CMA Calculations'!$H$1066
Name __vib01: #REF!
Name __vib02: #REF!
Name __vib03: #REF!
Name __vib04: #REF!
Name __vib05: #REF!
Name __vib06: #REF!
Name __vib07: #REF!
Name __WS1: #REF!
Name __WS2: #REF!
Name _1: #REF!
Name _15: #REF!
Name _15_2: #REF!
Name _3: #REF!
Name _CDD763: #REF!
Name _DAT1: "$#REF!.$A$1:$A$394"
Name _DAT10: #REF!
Name _DAT11: #REF!
Name _DAT12: #REF!
Name _DAT13: #REF!
Name _DAT14: #REF!
Name _DAT15: #REF!
Name _DAT16: #REF!

Sheet TB
B1: TB July 2020
B3: Ledger account | C3: Name | D3: Opening balance | E3: Debit | F3: Credit | G3: Closing balance | I3: MainAccount | J3: Name | K3: Opening balance | L3: Debit | M3: Credit | N3: Closing balance
B4: 1510000 | C4: Land | G4: =IFERROR(VLOOKUP(B4,$I$4:$N$27,6,FALSE),0) -> 102037368651 | H4: =LEFT(I4,3) -> 421 | I4: 4215400 | J4: Gain from Sold FA Machinary & Equipment- | K4: -12006757 | L4: 0 | M4: 0 | N4: -12006757 | P4: 102037368651 | Q4: =P4-N4 -> 102049375408
B5: 1520000 | C5: Buildings | G5: =IFERROR(VLOOKUP(B5,$I$4:$N$27,6,FALSE),0) -> 2.8312631e+11 | H5: =LEFT(I5,3) -> 421 | I5: 4215500 | J5: Gain from Sold FA Vehicles- | K5: -1.4130901e+09 | L5: 0 | M5: 0 | N5: -1.4130901e+09 | P5: 2.8331437e+11 | Q5: =P5-N5 -> 2.8472746e+11
B6: 1530000 | C6: Structures | G6: =IFERROR(VLOOKUP(B6,$I$4:$N$27,6,FALSE),0) -> 9.6658306e+09 | H6: =LEFT(I6,3) -> 421 | I6: 4215600 | J6: Gain from Sold FA Tools, Furniture & Fixtures- | K6: -30900901 | L6: 0 | M6: 0 | N6: -30900901 | P6: 9.4307277e+09 | Q6: =P6-N6 -> 9.4616286e+09
B7: 1540000 | C7: Machinery & Equipment | G7: =IFERROR(VLOOKUP(B7,$I$4:$N$27,6,FALSE),0) -> 7.7229168e+10 | H7: =LEFT(I7,3) -> 152 | I7: 1520000 | J7: Buildings- | K7: 2.8312631e+11 | L7: 0 | M7: 0 | N7: 2.8312631e+11 | P7: 7.8722001e+10 | Q7: =P7-N7 -> -2.0440431e+11
B8: 1550000 | C8: Vehicles | G8: =IFERROR(VLOOKUP(B8,$I$4:$N$27,6,FALSE),0) -> 4.3952486e+11 | H8: =LEFT(I8,3) -> 161 | I8: 1615500 | J8: Down Payment: Vehicles- | K8: 3335691892 | L8: 0 | M8: 471891891 | N8: 2863800001 | P8: 4.4178311e+11 | Q8: =P8-N8 -> 4.3891931e+11
B9: 1560000 | C9: Tools, Furniture & Fixtures | G9: =IFERROR(VLOOKUP(B9,$I$4:$N$27,6,FALSE),0) -> 1.4168663e+10 | H9: =LEFT(I9,3) -> 251 | I9: 2515200 | J9: Accumulated Depreciation: Building- | K9: -1.5718812e+11 | L9: 0 | M9: 1.1383784e+09 | N9: -1.583265e+11 | P9: 1.3614925e+10 | Q9: =P9-N9 -> 1.7194143e+11
B10: 1585400 | C10: Lease Hold Improvement Machine& Equipment | G10: =IFERROR(VLOOKUP(B10,$I$4:$N$27,6,FALSE),0) -> 0 | H10: =LEFT(I10,3) -> 161 | I10: 1615400 | J10: Down Payment: Machinary & Equipment- | K10: 0 | L10: 0 | M10: 0 | N10: 0 | P10: 620000000 | Q10: =P10-N10 -> 620000000
B11: 1585500 | C11: Lease Hold Improvement Vehicle | G11: =IFERROR(VLOOKUP(B11,$I$4:$N$27,6,FALSE),0) -> 0 | H11: =LEFT(I11,3) -> 156 | I11: 1560000 | J11: Tools, Furniture & Fixtures- | K11: 1.4168663e+10 | L11: 0 | M11: 0 | N11: 1.4168663e+10 | P11: 1434345000 | Q11: =P11-N11 -> -1.2734318e+10
B12: 1615200 | C12: Down Payment: Building | G12: =IFERROR(VLOOKUP(B12,$I$4:$N$27,6,FALSE),0) -> 0 | H12: =LEFT(I12,3) -> 151 | I12: 1510000 | J12: Land- | K12: 102037368651 | L12: 0 | M12: 0 | N12: 102037368651 | P12: 0 | Q12: =P12-N12 -> -102037368651
B13: 1615300 | C13: Down Payment: Structures | G13: =IFERROR(VLOOKUP(B13,$I$4:$N$27,6,FALSE),0) -> 0 | H13: =LEFT(I13,3) -> 154 | I13: 1540000 | J13: Machinery & Equipment- | K13: 7.7109498e+10 | L13: 119669272 | M13: 0 | N13: 7.7229168e+10 | P13: -1.1295559e+11 | Q13: =P13-N13 -> -1.9018475e+11
B14: 1615400 | C14: Down Payment: Machinary & Equipment | G14: =IFERROR(VLOOKUP(B14,$I$4:$N$27,6,FALSE),0) -> 0 | H14: =LEFT(I14,3) -> 153 | I14: 1530000 | J14: Structures- | K14: 9.6658306e+09 | L14: 0 | M14: 0 | N14: 9.6658306e+09 | P14: -7.9542433e+09 | Q14: =P14-N14 -> -1.7620074e+10
B15: 1615500 | C15: Down Payment: Vehicles | G15: =IFERROR(VLOOKUP(B15,$I$4:$N$27,6,FALSE),0) -> 2863800001 | H15: =LEFT(I15,3) -> 172 | I15: 1720000 | J15: System & Software- | K15: 156000000 | L15: 56670000 | M15: 0 | N15: 212670000 | P15: -6.5588325e+10 | Q15: =P15-N15 -> -6.5800995e+10
... B18: 2515400 | C18: Accumulated Depreciation: Machine | G18: =IFERROR(VLOOKUP(B18,$I$4:$N$27,6,FALSE),0) -> -6.8709828e+10 | H18: =LEFT(I18,3) -> 251 | I18: 2515400 | J18: Accumulated Depreciation: Machine- | K18: -6.8540838e+10 | L18: 0 | M18: 1.6899033e+08 | N18: -6.8709828e+10 | P18: -1.1221614e+09 | Q18: =P18-N18 -> 6.7587666e+10
B19: 2515500 | C19: Accumulated Depreciation: Vehicles | G19: =IFERROR(VLOOKUP(B19,$I$4:$N$27,6,FALSE),0) -> -3.3108136e+11 | H19: =LEFT(I19,3) -> 251 | I19: 2515300 | J19: Accumulated Depreciation: Structures- | K19: -9.0126204e+09 | L19: 0 | M19: 20322217 | N19: -9.0329426e+09
B20: 2515600 | C20: Accumulated Depreciation: Tools, Furniture & Fixtures | G20: =IFERROR(VLOOKUP(B20,$I$4:$N$27,6,FALSE),0) -> -1.1129343e+10 | H20: =LEFT(I20,3) -> 254 | I20: 2540000 | J20: Accumulated Depreciation: System & Software- | K20: -26260000 | L20: 0 | M20: 3669500 | N20: -29929500
B21: 1615600 | C21: Down Payment: Tools, Furniture & Fixtures | G21: =IFERROR(VLOOKUP(B21,$I$4:$N$27,6,FALSE),0) -> 0 | H21: =LEFT(I21,3) -> 251 | I21: 2515500 | J21: Accumulated Depreciation: Vehicles- | K21: -3.2873047e+11 | L21: 5.67e+08 | M21: 2.9178912e+09 | N21: -3.3108136e+11
B22: 4215500 | C22: Gain from Sold FA Vehicles | G22: =IFERROR(VLOOKUP(B22,$I$4:$N$27,6,FALSE),0) -> -1.4130901e+09 | I22: 1615600 | J22: Down Payment: Tools, Furniture & Fixtures- | K22: 0 | L22: 0 | M22: 0 | N22: 0
B23: 4215600 | C23: Gain from Sold FA Tools, Furniture & Fixtures | G23: =IFERROR(VLOOKUP(B23,$I$4:$N$27,6,FALSE),0) -> -30900901
B24: 4215400 | C24: Gain from Sold FA Machinary & Equipment | G24: =IFERROR(VLOOKUP(B24,$I$4:$N$27,6,FALSE),0) -> -12006757
B25: 4215200 | C25: Gain from Sold FA Building | G25: =IFERROR(VLOOKUP(B25,$I$4:$N$27,6,FALSE),0) -> 0
B26: 1720000 | C26: System & Software | G26: =IFERROR(VLOOKUP(B26,$I$4:$N$27,6,FALSE),0) -> 212670000
B27: 2540000 | C27: Accumulated Depreciation: System & Software | G27: =IFERROR(VLOOKUP(B27,$I$4:$N$27,6,FALSE),0) -> -29929500
D30: =H4&"*,"&H5&"*,"&H6&"*,"&H7&"*,"&H8&"*,"&H9&"*,"&H10&"*,"&H11&"*,"&H13&"*,"&H14&"*,"&H15&"*,"&H16&"*,"&H17&"*,"&H18&"*,"&H19&"*,"&H20&"*,"&H12 -> 421*,421*,421*,152*,161*,251*,161*,156*,154*,153*,172*,155*,251*,251*,251*,254*,151
D31: 151*,152*,153*,154*,155*,156*,161*,251*,161*158*,42*,17*,254*
J35: MNE000001
J36: MNE000002
J37: MNE000003
J38: MNE000004
J39: MNE000005
J40: MNE000006
J41: MNE000007
J42: MNE000008
J43: FNF000002
J44: FNF000003
J45: FNF000004
J46: FNF000005
... J53: FNF000047

Sheet TOTAL
A1: PT. Sankyu Indonesia International
A2: Total of Fixed Asset
A3: 30 September 2025
A5: No. | B5: Name of Fixed Assets | C5: Fixed Asset (List) | I5: D365
C6: Beginning Balance | D6: Additional | E6: Disposals | F6: Adjustment | G6: Ending Balace | I6: Total | J6: Different
G7: a | I7: b | J7: c = a - b
A8: Purchase Price
A9: 152 | B9: Buildings | C9: 2.8312631e+11 | D9: =SUMIFS(FA_2025!$T$26:$T$38,FA_2025!$D$26:$D$38,TOTAL!$A$9,FA_2025!$AR$26:$AR$38,TOTAL!$D$6) -> 0 | E9: =-SUMIFS(FA_2025!$T$26:$T$38,FA_2025!$D$26:$D$38,TOTAL!$A$9,FA_2025!$AS$26:$AS$38,TOTAL!$E$6) -> 0 | G9: =+C9+D9+E9+F9 -> 2.8312631e+11 | I9: =TB!G5 -> 2.8312631e+11 | J9: =+G9-I9 -> 0
A10: 153 | B10: Structures | C10: 9.6658306e+09 | D10: =SUMIFS(FA_2025!$T$39:$T$63,FA_2025!$D$39:$D$63,TOTAL!$A$10,FA_2025!$AR$39:$AR$63,TOTAL!$D$6) -> 0 | E10: =-SUMIFS(FA_2025!$T$39:$T$63,FA_2025!$D$39:$D$63,TOTAL!$A$10,FA_2025!$AS$39:$AS$63,TOTAL!$E$6) -> 0 | G10: =+C10+D10+E10+F10 -> 9.6658306e+09 | I10: =TB!G6 -> 9.6658306e+09 | J10: =+G10-I10 -> 0
A11: 154 | B11: Machinery & Equipments | C11: 7.9065598e+10 | D11: =SUMIFS(FA_2025!$T$64:$T$101,FA_2025!$D$64:$D$101,TOTAL!$A$11,FA_2025!$AR$64:$AR$101,TOTAL!$D$6) -> 145223481 | E11: =-SUMIFS(FA_2025!$T$64:$T$101,FA_2025!$D$64:$D$101,TOTAL!$A$11,FA_2025!$AS$64:$AS$101,TOTAL!$E$6) -> 0 | G11: =+C11+D11+E11+F11 -> 7.9210821e+10 | I11: =TB!G7 -> 7.7229168e+10 | J11: =+G11-I11 -> 1981653528
A12: 159 | B12: Vessels | C12: 0 | D12: 0 | E12: 0 | G12: =+C12+D12+E12+F12 -> 0 | I12: 0 | J12: =+G12-I12 -> 0
A13: 155 | B13: Vehicles | C13: 4.2545379e+11 | D13: =SUMIFS(FA_2025!$T$102:$T$219,FA_2025!$D$102:$D$219,TOTAL!$A$13,FA_2025!$AR$102:$AR$219,TOTAL!$D$6) -> 4433108108 | E13: =-SUMIFS(FA_2025!$T$102:$T$219,FA_2025!$D$102:$D$219,TOTAL!$A$13,FA_2025!$AS$102:$AS$219,TOTAL!$E$6) -> -4.5663943e+09 | G13: =C13+D13+E13+F13 -> 4.253205e+11 | I13: =TB!G8 -> 4.3952486e+11 | J13: =+G13-I13 -> -1.4204357e+10
A14: 156 | B14: Tools, Furnitures & Fixtures | C14: 1.4017656e+10 | D14: =SUMIFS(FA_2025!$T$220:$T$250,FA_2025!$D$220:$D$250,TOTAL!$A$14,FA_2025!$AR$220:$AR$250,TOTAL!$D$6) -> 122000000 | E14: =-SUMIFS(FA_2025!$T$220:$T$250,FA_2025!$D$220:$D$250,TOTAL!$A$14,FA_2025!$AS$220:$AS$250,TOTAL!$E$6) -> 0 | G14: =+C14+D14+E14+F14 -> 1.4139656e+10 | I14: =TB!G9 -> 1.4168663e+10 | J14: =+G14-I14 -> -29007666
A15: 172 | B15: System | C15: 109050000 | D15: =SUMIFS(FA_2025!$T$220:$T$250,FA_2025!$D$220:$D$250,TOTAL!$A$15,FA_2025!$AR$220:$AR$250,TOTAL!$D$6) -> 0 | E15: =-SUMIFS(FA_2025!$T$220:$T$250,FA_2025!$D$220:$D$250,TOTAL!$A$15,FA_2025!$AS$220:$AS$250,TOTAL!$E$6) -> 0 | G15: =+C15+D15+E15+F15 -> 109050000 | I15: =TB!G26 -> 212670000 | J15: =+G15-I15 -> -103620000
A16: 151 | B16: Land | C16: 102037368651 | D16: =-SUMIFS(FA_2025!$T$256:$T$330,FA_2025!$D$256:$D$330,TOTAL!$A$16,FA_2025!$AR$256:$AR$330,TOTAL!$D$6) -> 0 | E16: =-SUMIFS(FA_2025!#REF!,FA_2025!#REF!,TOTAL!$A$16,FA_2025!#REF!,TOTAL!$E$6) -> #REF! | G16: =+C16+D16+E16+F16 -> #REF! | I16: 102037368651 | J16: =+G16-I16 -> #REF!
A17: 161 | B17: Construction In Process | C17: 4108230270 | D17: =SUMIFS(FA_2025!$T$256:$T$256,FA_2025!$D$256:$D$256,TOTAL!$A$17,FA_2025!$AR$256:$AR$256,TOTAL!$D$6) -> 0 | E17: =-SUMIFS(FA_2025!$AQ$256:$AQ$256,FA_2025!$D$256:$D$256,TOTAL!$A$17,FA_2025!$AS$256:$AS$256,TOTAL!$E$6) -> 0 | G17: =+C17+D17+E17+F17 -> 4108230270 | I17: =SUM(TB!G12:G15,TB!G21) -> 2863800001 | J17: =+G17-I17 -> 1244430269
B18: Grand Total | C18: 9.1758383e+11 | D18: =SUM(D9:D17) -> 4700331589 | E18: =SUM(E9:E17) -> #REF! | F18: =SUM(F9:F17) -> 0 | G18: =SUM(G9:G17) -> #REF! | I18: =SUM(I9:I17) -> 9.2882867e+11 | J18: =SUM(J9:J17) -> #REF!
C19: 9.134756e+11 | G19: =G18-G17 -> #REF!
A20: Accumulated Depreciation (251)
A21: 152 | B21: Buildings | C21: 1.480811e+11 | D21: =SUM(FA_2025!#REF!) -> #REF! | E21: =-SUMIFS(FA_2025!$AP$26:$AP$1036,FA_2025!$D$26:$D$1036,TOTAL!$A21,FA_2025!$AS$26:$AS$1036,TOTAL!$E$6) -> 0 | G21: =+C21+D21+E21+F21 -> #REF! | I21: =TB!G16 -> -1.583265e+11 | J21: =+G21+I21 -> #REF!
A22: 153 | B22: Structures | C22: 8.8439239e+09 | D22: =SUM(FA_2025!#REF!) -> #REF! | E22: =-SUMIFS(FA_2025!$AP$26:$AP$1036,FA_2025!$D$26:$D$1036,TOTAL!$A22,FA_2025!$AS$26:$AS$1036,TOTAL!$E$6) -> 0 | G22: =+C22+D22+E22+F22 -> #REF! | I22: =TB!G17 -> -9.0329426e+09 | J22: =+G22+I22 -> #REF!
A23: 154 | B23: Machinery & Equipments | C23: 6.9407991e+10 | D23: =SUM(FA_2025!#REF!) -> #REF! | E23: =-SUMIFS(FA_2025!$AP$26:$AP$1036,FA_2025!$D$26:$D$1036,TOTAL!$A23,FA_2025!$AS$26:$AS$1036,TOTAL!$E$6) -> 0 | G23: =+C23+D23+E23+F23 -> #REF! | I23: =TB!G18 -> -6.8709828e+10 | J23: =+G23+I23 -> #REF!
A24: 159 | B24: Vessels | C24: 0 | D24: 0 | E24: =-SUMIFS(FA_2025!$AP$26:$AP$1036,FA_2025!$D$26:$D$1036,TOTAL!$A24,FA_2025!$AS$26:$AS$1036,TOTAL!$E$6) -> 0 | G24: =+C24+D24+E24+F24 -> 0 | J24: =+G24+I24 -> 0
A25: 155 | B25: Vehicles | C25: 3.3226321e+11 | D25: =SUM(FA_2025!#REF!) -> #REF! | E25: =-SUMIFS(FA_2025!$AP$26:$AP$1036,FA_2025!$D$26:$D$1036,TOTAL!$A25,FA_2025!$AS$26:$AS$1036,TOTAL!$E$6) -> -4.5663943e+09 | G25: =+C25+D25+E25+F25 -> #REF! | I25: =TB!G19 -> -3.3108136e+11 | J25: =+G25+I25 -> #REF!
A26: 156 | B26: Tools, Furnitures & Fixtures | C26: 1.0974552e+10 | D26: =SUM(FA_2025!#REF!) -> #REF! | E26: =-SUMIFS(FA_2025!$AP$26:$AP$1036,FA_2025!$D$26:$D$1036,TOTAL!$A26,FA_2025!$AS$26:$AS$1036,TOTAL!$E$6) -> 0 | G26: =+C26+D26+E26+F26 -> #REF! | I26: =TB!G20 -> -1.1129343e+10 | J26: =+G26+I26 -> #REF!
A27: 172 | B27: System | C27: 9155000 | D27: =SUM(FA_2025!#REF!) -> #REF! | E27: =-SUMIFS(FA_2025!$AP$26:$AP$1036,FA_2025!$D$26:$D$1036,TOTAL!$A27,FA_2025!$AS$26:$AS$1036,TOTAL!$E$6) -> 0 | G27: =+C27+D27+E27+F27 -> #REF! | I27: =TB!G27 -> -29929500 | J27: =+G27+I27 -> #REF!
B28: Grand Total | C28: 5.6957993e+11 | D28: =SUM(D21:D27) -> #REF! | E28: =SUM(E21:E27) -> -4.5663943e+09 | F28: =SUM(F21:F27) -> 0 | G28: =SUM(G21:G27) -> #REF! | I28: =SUM(I21:I27) -> -5.783099e+11 | J28: =SUM(J21:J26) -> #REF!
C30: =C18-C28 -> 3.480039e+11 | E30: Fixed Asset (Net) | G30: =+G18-G28 -> #REF!
A31: Net Book Value (251) | C31: =C30+C40 -> #REF!
A32: 151 | B32: Land | C32: =G16 -> #REF!
A33: 152 | B33: Buildings | C33: =G9-G21 -> #REF!
A34: 153 | B34: Structures | C34: =G10-G22 -> #REF!
A35: 154 | B35: Machinery & Equipments | C35: =G11-G23 -> #REF!
A36: 159 | B36: Vessels | C36: =G12-G24 -> 0
A37: 155 | B37: Vehicles | C37: =G13-G25 -> #REF!
A38: 156 | B38: Tools, Furnitures & Fixtures | C38: =G14-G26 -> #REF!
A39: 172 | B39: System | C39: =G15-G27 -> #REF!
C40: =SUM(C32:C38) -> #REF!

Sheet FA_2025
A1: PT. SANKYU INDONESIA INTERNATIONAL
A2: LIST OF FIXED ASSETS AND DEPRECIATION SCHEDULE
A3: 46022
F5: CATEGORY | G5: JANUARY | H5: FEBRUARY | I5: MARCH | J5: APRIL | K5: MAY | L5: JUNE | M5: JULY | N5: AUGUST | O5: SEPTEMBER | P5: OCTOBER | Q5: NOVEMBER | R5: DECEMBER | S5: TOTAL/YEAR
E6: Warehouse 1 | F6: WH1 | G6: =SUMIF($E$25:$E$280,F6,$AD$25:$AD$280) -> 3.034665e+08 | H6: =SUMIF($E$25:$E$281,F6,$AE$25:$AE$281) -> 3.034665e+08 | I6: =SUMIF($E$25:$E$281,F6,$AF$25:$AF$281) -> 3.034665e+08 | J6: =SUMIF($E$25:$E$281,F6,$AG$25:$AG$281) -> 3.034665e+08 | K6: =SUMIF($E$25:$E$281,F6,$AH$25:$AH$281) -> 3.034665e+08 | L6: =SUMIF($E$25:$E$281,F6,$AI$25:$AI$280) -> 3.034665e+08 | M6: =SUMIF($E$25:$E$281,F6,$AJ$25:$AJ$281) -> 3.034665e+08 | N6: =SUMIF($E$25:$E$280,F6,$AK$25:$AK$280) -> 3.034665e+08 | O6: =SUMIF($E$25:$E$280,F6,$AL$25:$AL$280) -> 3.034665e+08 | P6: =SUMIF($E$25:$E$280,F6,$AM$25:$AM$280) -> 3.034665e+08 | Q6: =SUMIF($E$25:$E$280,F6,$AN$25:$AN$280) -> 3.034665e+08 | R6: =SUMIF($E$25:$E$280,F6,$AO$25:$AO$280) -> 3.034665e+08 | S6: =SUM(G6:R6) -> 3.641598e+09
E7: Warehouse 2 | F7: WH2 | G7: =SUMIF($E$25:$E$280,F7,$AD$25:$AD$280) -> 6.5201362e+08 | H7: =SUMIF($E$25:$E$280,F7,$AE$25:$AE$280) -> 6.5201362e+08 | I7: =SUMIF($E$25:$E$280,F7,$AF$25:$AF$280) -> 6.5201362e+08 | J7: =SUMIF($E$25:$E$280,F7,$AG$25:$AG$280) -> 6.5201362e+08 | K7: =SUMIF($E$25:$E$280,F7,$AH$25:$AH$280) -> 6.5201362e+08 | L7: =SUMIF($E$25:$E$280,F7,$AI$25:$AI$280) -> 6.5201362e+08 | M7: =SUMIF($E$25:$E$280,F7,$AJ$25:$AJ$280) -> 6.5201362e+08 | N7: =SUMIF($E$25:$E$280,F7,$AK$25:$AK$280) -> 6.5201362e+08 | O7: =SUMIF($E$25:$E$280,F7,$AL$25:$AL$280) -> 6.5201362e+08 | P7: =SUMIF($E$25:$E$280,F7,$AM$25:$AM$280) -> 6.5201362e+08 | Q7: =SUMIF($E$25:$E$280,F7,$AN$25:$AN$280) -> 6.5201362e+08 | R7: =SUMIF($E$25:$E$280,F7,$AO$25:$AO$280) -> 6.5201362e+08 | S7: =SUM(G7:R7) -> 7.8241634e+09
E8: Transport | F8: TRP | G8: =SUMIF($E$25:$E$281,F8,$AD$25:$AD$280) -> 12888438 | H8: =SUMIF($E$25:$E$281,F8,$AE$25:$AE$280) -> 12888438 | I8: =SUMIF($E$25:$E$280,F8,$AF$25:$AF$281) -> 12888438 | J8: =SUMIF($E$25:$E$280,F8,$AG$25:$AG$280) -> 31452402 | K8: =SUMIF($E$25:$E$280,F8,$AH$25:$AH$280) -> 31452402 | L8: =SUMIF($E$25:$E$280,F8,$AI$25:$AI$280) -> 31452402 | M8: =SUMIF($E$25:$E$280,F8,$AJ$25:$AJ$280) -> 31452402 | N8: =SUMIF($E$25:$E$280,F8,$AK$25:$AK$280) -> 31452402 | O8: =SUMIF($E$25:$E$280,F8,$AL$25:$AL$280) -> 64723574 | P8: =SUMIF($E$25:$E$280,F8,$AM$25:$AM$280) -> 67290240 | Q8: =SUMIF($E$25:$E$280,F8,$AN$25:$AN$280) -> 67290240 | R8: =SUMIF($E$25:$E$280,F8,$AO$25:$AO$280) -> 67290240 | S8: =SUM(G8:R8) -> 4.6252162e+08
E9: Bali | F9: BALI | G9: =SUMIF($E$25:$E$281,F9,$AD$25:$AD$280) -> 14100000 | H9: =SUMIF($E$25:$E$281,F9,$AE$25:$AE$280) -> 14100000 | I9: =SUMIF($E$25:$E$280,F9,$AF$25:$AF$281) -> 14100000 | J9: =SUMIF($E$25:$E$280,F9,$AG$25:$AG$280) -> 14100000 | K9: =SUMIF($E$25:$E$280,F9,$AH$25:$AH$280) -> 14100000 | L9: =SUMIF($E$25:$E$280,F9,$AI$25:$AI$280) -> 1.1998584e+08 | M9: =SUMIF($E$25:$E$280,F9,$AJ$25:$AJ$280) -> 1.1998584e+08 | N9: =SUMIF($E$25:$E$280,F9,$AK$25:$AK$280) -> 1.1998584e+08 | O9: =SUMIF($E$25:$E$280,F9,$AL$25:$AL$280) -> 1.1998584e+08 | P9: =SUMIF($E$25:$E$280,F9,$AM$25:$AM$280) -> 1.1998584e+08 | Q9: =SUMIF($E$25:$E$280,F9,$AN$25:$AN$280) -> 1.1998584e+08 | R9: =SUMIF($E$25:$E$280,F9,$AO$25:$AO$280) -> 1.1998584e+08 | S9: =SUM(G9:R9) -> 9.1040086e+08
E10: Medan | F10: MDN | G10: =SUMIF($E$25:$E$281,F10,$AD$25:$AD$280) -> 0 | H10: =SUMIF($E$25:$E$281,F10,$AE$25:$AE$280) -> 0 | I10: =SUMIF($E$25:$E$280,F10,$AF$25:$AF$281) -> 0 | J10: =SUMIF($E$25:$E$280,F10,$AG$25:$AG$280) -> 0 | K10: =SUMIF($E$25:$E$280,F10,$AH$25:$AH$280) -> 0 | L10: =SUMIF($E$25:$E$280,F10,$AI$25:$AI$280) -> 0 | M10: =SUMIF($E$25:$E$280,F10,$AJ$25:$AJ$280) -> 0 | N10: =SUMIF($E$25:$E$280,F10,$AK$25:$AK$280) -> 0 | O10: =SUMIF($E$25:$E$280,F10,$AL$25:$AL$280) -> 0 | P10: =SUMIF($E$25:$E$280,F10,$AM$25:$AM$280) -> 0 | Q10: =SUMIF($E$25:$E$280,F10,$AN$25:$AN$280) -> 0 | R10: =SUMIF($E$25:$E$280,F10,$AO$25:$AO$280) -> 0 | S10: =SUM(G10:R10) -> 0
E11: Palembang | F11: PBG | G11: =SUMIF($E$25:$E$281,F11,$AD$25:$AD$280) -> 13333333 | H11: =SUMIF($E$25:$E$281,F11,$AE$25:$AE$280) -> 13333333 | I11: =SUMIF($E$25:$E$280,F11,$AF$25:$AF$281) -> 13333333 | J11: =SUMIF($E$25:$E$280,F11,$AG$25:$AG$280) -> 13333333 | K11: =SUMIF($E$25:$E$280,F11,$AH$25:$AH$280) -> 13333333 | L11: =SUMIF($E$25:$E$280,F11,$AI$25:$AI$280) -> 13333333 | M11: =SUMIF($E$25:$E$280,F11,$AJ$25:$AJ$280) -> 13333333 | N11: =SUMIF($E$25:$E$280,F11,$AK$25:$AK$280) -> 13333333 | O11: =SUMIF($E$25:$E$280,F11,$AL$25:$AL$280) -> 13333333 | P11: =SUMIF($E$25:$E$280,F11,$AM$25:$AM$280) -> 13333333 | Q11: =SUMIF($E$25:$E$280,F11,$AN$25:$AN$280) -> 13333333 | R11: =SUMIF($E$25:$E$280,F11,$AO$25:$AO$280) -> 13333333 | S11: =SUM(G11:R11) -> 159999996
E12: Makassar | F12: MKS | G12: =SUMIF($E$25:$E$281,F12,$AD$25:$AD$280) -> 0 | H12: =SUMIF($E$25:$E$281,F12,$AE$25:$AE$280) -> 0 | I12: =SUMIF($E$25:$E$280,F12,$AF$25:$AF$281) -> 0 | J12: =SUMIF($E$25:$E$280,F12,$AG$25:$AG$280) -> 0 | K12: =SUMIF($E$25:$E$280,F12,$AH$25:$AH$280) -> 0 | L12: =SUMIF($E$25:$E$280,F12,$AI$25:$AI$280) -> 0 | M12: =SUMIF($E$25:$E$280,F12,$AJ$25:$AJ$280) -> 0 | N12: =SUMIF($E$25:$E$280,F12,$AK$25:$AK$280) -> 0 | O12: =SUMIF($E$25:$E$280,F12,$AL$25:$AL$280) -> 0 | P12: =SUMIF($E$25:$E$280,F12,$AM$25:$AM$280) -> 0 | Q12: =SUMIF($E$25:$E$280,F12,$AN$25:$AN$280) -> 0 | R12: =SUMIF($E$25:$E$280,F12,$AO$25:$AO$280) -> 0 | S12: =SUM(G12:R12) -> 0
E13: Surabaya | F13: SBY | G13: =SUMIF($E$25:$E$281,F13,$AD$25:$AD$280) -> 74120370 | H13: =SUMIF($E$25:$E$281,F13,$AE$25:$AE$280) -> 74120370 | I13: =SUMIF($E$25:$E$280,F13,$AF$25:$AF$281) -> 74120370 | J13: =SUMIF($E$25:$E$280,F13,$AG$25:$AG$280) -> 74120370 | K13: =SUMIF($E$25:$E$280,F13,$AH$25:$AH$280) -> 74120370 | L13: =SUMIF($E$25:$E$280,F13,$AI$25:$AI$280) -> 74120370 | M13: =SUMIF($E$25:$E$280,F13,$AJ$25:$AJ$280) -> 74120370 | N13: =SUMIF($E$25:$E$280,F13,$AK$25:$AK$280) -> 0 | O13: =SUMIF($E$25:$E$280,F13,$AL$25:$AL$280) -> 0 | P13: =SUMIF($E$25:$E$280,F13,$AM$25:$AM$280) -> 0 | Q13: =SUMIF($E$25:$E$280,F13,$AN$25:$AN$280) -> 0 | R13: =SUMIF($E$25:$E$280,F13,$AO$25:$AO$280) -> 0 | S13: =SUM(G13:R13) -> 518842590
E14: Forklift, Shuttle Car, Equipment, Nestainer Rack | F14: OTHERS | G14: =SUMIF($E$25:$E$281,F14,$AD$25:$AD$280) -> 98631187 | H14: =SUMIF($E$25:$E$281,F14,$AE$25:$AE$280) -> 1.2068119e+08 | I14: =SUMIF($E$25:$E$280,F14,$AF$25:$AF$281) -> 1.2068119e+08 | J14: =SUMIF($E$25:$E$280,F14,$AG$25:$AG$280) -> 1.2068119e+08 | K14: =SUMIF($E$25:$E$280,F14,$AH$25:$AH$280) -> 1.2068119e+08 | L14: =SUMIF($E$25:$E$280,F14,$AI$25:$AI$280) -> 1.2068119e+08 | M14: =SUMIF($E$25:$E$280,F14,$AJ$25:$AJ$280) -> 1.1380285e+08 | N14: =SUMIF($E$25:$E$280,F14,$AK$25:$AK$280) -> 1.1380285e+08 | O14: =SUMIF($E$25:$E$280,F14,$AL$25:$AL$280) -> 1.1380285e+08 | P14: =SUMIF($E$25:$E$280,F14,$AM$25:$AM$280) -> 1.1746952e+08 | Q14: =SUMIF($E$25:$E$280,F14,$AN$25:$AN$280) -> 1.1746952e+08 | R14: =SUMIF($E$25:$E$280,F14,$AO$25:$AO$280) -> 1.1746952e+08 | S14: =SUM(G14:R14) -> 1.3958542e+09
G15: =SUBTOTAL(9,G6:G14) -> 1.1685534e+09 | H15: =SUBTOTAL(9,H6:H14) -> 1.1906034e+09 | I15: =SUBTOTAL(9,I6:I14) -> 1.1906034e+09 | J15: =SUBTOTAL(9,J6:J14) -> 1.2091674e+09 | K15: =SUBTOTAL(9,K6:K14) -> 1.2091674e+09 | L15: =SUBTOTAL(9,L6:L14) -> 1.3150532e+09 | M15: =SUBTOTAL(9,M6:M14) -> 1.3081749e+09 | N15: =SUBTOTAL(9,N6:N14) -> 1.2340545e+09 | ... S15: =SUBTOTAL(9,S6:S14) -> 1.4913381e+10
F17: SITE | G17: JANUARY | H17: FEBRUARY | I17: MARCH | J17: APRIL | K17: MAY | L17: JUNE | M17: JULY | N17: AUGUST | O17: SEPTEMBER | P17: OCTOBER | Q17: NOVEMBER | R17: DECEMBER | S17: TOTAL/YEAR
F18: CLCWH | G18: =SUMIF($C$25:$C$280,F18,$AD$25:$AD$280) -> 1.0682113e+09 | H18: =SUMIF($C$25:$C$280,F18,$AE$25:$AE$280) -> 1.0902613e+09 | I18: =SUMIF($C$25:$C$280,F18,$AF$25:$AF$280) -> 1.0902613e+09 | J18: =SUMIF($C$25:$C$280,F18,$AG$25:$AG$280) -> 1.0902613e+09 | K18: =SUMIF($C$25:$C$280,F18,$AH$25:$AH$280) -> 1.0902613e+09 | L18: =SUMIF($C$25:$C$280,F18,$AI$25:$AI$280) -> 1.0902613e+09 | M18: =SUMIF($C$25:$C$280,F18,$AJ$25:$AJ$280) -> 1.083383e+09 | N18: =SUMIF($C$25:$C$280,F18,$AK$25:$AK$280) -> 1.083383e+09 | O18: =SUMIF($C$25:$C$280,F18,$AL$25:$AL$280) -> 1.083383e+09 | P18: =SUMIF($C$25:$C$280,F18,$AM$25:$AM$280) -> 1.0870496e+09 | Q18: =SUMIF($C$25:$C$280,F18,$AN$25:$AN$280) -> 1.0870496e+09 | R18: =SUMIF($C$25:$C$280,F18,$AO$25:$AO$280) -> 1.0870496e+09 | S18: =SUM(G18:R18) -> 1.3030816e+10
F19: CLCOWH | G19: =SUMIF($C$25:$C$280,F19,$AD$25:$AD$280) -> 87453703 | H19: =SUMIF($C$25:$C$280,F19,$AE$25:$AE$280) -> 87453703 | I19: =SUMIF($C$25:$C$280,F19,$AF$25:$AF$280) -> 87453703 | J19: =SUMIF($C$25:$C$280,F19,$AG$25:$AG$280) -> 87453703 | K19: =SUMIF($C$25:$C$280,F19,$AH$25:$AH$280) -> 87453703 | L19: =SUMIF($C$25:$C$280,F19,$AI$25:$AI$280) -> 1.9333954e+08 | M19: =SUMIF($C$25:$C$280,F19,$AJ$25:$AJ$280) -> 1.9333954e+08 | N19: =SUMIF($C$25:$C$280,F19,$AK$25:$AK$280) -> 1.1921917e+08 | O19: =SUMIF($C$25:$C$280,F19,$AL$25:$AL$280) -> 1.1921917e+08 | P19: =SUMIF($C$25:$C$280,F19,$AM$25:$AM$280) -> 1.1921917e+08 | Q19: =SUMIF($C$25:$C$280,F19,$AN$25:$AN$280) -> 1.1921917e+08 | R19: =SUMIF($C$25:$C$280,F19,$AO$25:$AO$280) -> 1.1921917e+08 | S19: =SUM(G19:R19) -> 1.4200434e+09
F20: CLCTRP | G20: =SUMIF($C$25:$C$280,F20,$AD$25:$AD$280) -> 12888438 | H20: =SUMIF($C$25:$C$280,F20,$AE$25:$AE$280) -> 12888438 | I20: =SUMIF($C$25:$C$280,F20,$AF$25:$AF$280) -> 12888438 | J20: =SUMIF($C$25:$C$280,F20,$AG$25:$AG$280) -> 31452402 | K20: =SUMIF($C$25:$C$280,F20,$AH$25:$AH$280) -> 31452402 | L20: =SUMIF($C$25:$C$280,F20,$AI$25:$AI$280) -> 31452402 | M20: =SUMIF($C$25:$C$280,F20,$AJ$25:$AJ$280) -> 31452402 | N20: =SUMIF($C$25:$C$280,F20,$AK$25:$AK$280) -> 31452402 | O20: =SUMIF($C$25:$C$280,F20,$AL$25:$AL$280) -> 64723574 | P20: =SUMIF($C$25:$C$280,F20,$AM$25:$AM$280) -> 67290240 | Q20: =SUMIF($C$25:$C$280,F20,$AN$25:$AN$280) -> 67290240 | R20: =SUMIF($C$25:$C$280,F20,$AO$25:$AO$280) -> 67290240 | S20: =SUM(G20:R20) -> 4.6252162e+08
G21: =SUM(G18:G20) -> 1.1685534e+09 | H21: =SUM(H18:H20) -> 1.1906034e+09 | I21: =SUM(I18:I20) -> 1.1906034e+09 | J21: =SUM(J18:J20) -> 1.2091674e+09 | K21: =SUM(K18:K20) -> 1.2091674e+09 | L21: =SUM(L18:L20) -> 1.3150532e+09 | M21: =SUM(M18:M20) -> 1.3081749e+09 | N21: =SUM(N18:N20) -> 1.2340545e+09 | ... S21: =SUM(S18:S20) -> 1.4913381e+10
A23: No. | B23: Site/ Location | C23: Job | D23: Account | E23: Category | F23: Asset | G23: Fixed asset number | H23: Purchase Date | I23: Group | J23: Voucher | K23: Name of Fixed Asset | L23: Maker/Type/Location | M23: Capacity/Size/User | N23: Year | O23: Police | P23: Machine | Q23: Chasis | R23: Quantity | S23: Valas | T23: Purchase Price | U23: Monthly Depreciation | V23: Depreciation Period | AA23: Accumulated Depreciation | AB23: Net Book Value | AC23: Depreciation Expense Current | AD23: DEPRECIATION 2025 ( MONTHLY ) | AP23: Accumulated Depreciation | AQ23: Net Book Value | AR23: Status | AT23: Acquisition | AU23: Remark | AV23: Photo Status | AX23: Checker Name ( A ) | AZ23: Existing ( B ) | BB23: If Yes (Existing) ( C ) | BD23: If Not Used ( D ) | BF23: Sticker ( E )
D24: No. | F24: No. | G24: AX | J24: No. | O24: No. | P24: No. | Q24: No. | V24: Total | W24: Acc. 2024 | X24: Yearly 2025 | Y24: Until 2025 | Z24: Remain > 2026 | AA24: 45657 | AB24: 45657 | AC24: =+A3 -> 46022 | AD24: Jan | AE24: Feb | AF24: Mar | AG24: Apr | AH24: May | AI24: Jun | AJ24: Jul | AK24: Aug | AL24: Sep | AM24: Oct | AN24: Nov | AO24: Dec | AP24: =A3 -> 46022 | AQ24: =+AP24 -> 46022 | AR24: Additional | AS24: Disposals | AT24: Condition | AX24: Site | AY24: HO | AZ24: Yes | BA24: No | BB24: Still Used | BC24: Not Used | BD24: Repair | BE24: Disposals | BF24: Good | BG24: Bad
T25: a | U25: b=a:c | V25: c | W25: d=h:b | X25: e=j:b | Y25: f=d+e | Z25: g=c-f | AA25: l=h+j | AB25: m=a-l | AC25: j=total k (jAC-des) | AD25: k | AE25: k | AF25: k | AG25: k | AH25: k | AI25: k | AJ25: k | AK25: k | AL25: k | AM25: k | AN25: k | AO25: k | AP25: l=h+j | AQ25: m=a-l | AW25: Check
A26: 1 | B26: CLC | C26: CLCWH | D26: 152 | E26: WH1 | F26: CLC131-001 | G26: BLD000048 | H26: 41639 | I26: Building | J26: 111 | K26: Cikarang Warehouse and Office | L26: Kawasan Industri Terpadu Indonesia China (KITIC) Kav. 20, Cikarang, West Java | M26: Head Ofice & Cikarang Logistic | N26: 2013 | R26: 1 | T26: 7.1701319e+10 | U26: =+T26/V26 -> 2.987555e+08 | V26: 240 | W26: 133 | X26: =+AC26/U26 -> 12 | Y26: =+W26+X26 -> 145 | Z26: =+V26-Y26 -> 95 | AA26: 3.9734481e+10 | AB26: 3.1966838e+10 | AC26: =SUM(AD26:AO26) -> 3.585066e+09 | AD26: 2.987555e+08 | AE26: 2.987555e+08 | AF26: 2.987555e+08 | AG26: 2.987555e+08 | AH26: 2.987555e+08 | AI26: 2.987555e+08 | AJ26: 2.987555e+08 | AK26: 2.987555e+08 | AL26: 2.987555e+08 | AM26: 2.987555e+08 | AN26: 2.987555e+08 | AO26: 2.987555e+08 | AP26: =+AA26+AC26 -> 4.3319547e+10 | AQ26: =IF(AS26=$AS$24,((T26-AP26)*0),T26-AP26) -> 2.8381772e+10 | AV26: Ok | AW26: =IFERROR(VLOOKUP(G26,'[70]Detail Deprec_202508'!$D$33:$I$357,6,FALSE),0) -> 2.987555e+08 | AX26: =AW26-AK26 -> 0.00058341026
A27: 2 | B27: CLC | C27: CLCWH | D27: 152 | E27: WH2 | F27: CLC131-004 | G27: BLD000063 | H27: 42398 | I27: Building | J27: 84 | K27: IMB Tax Warehouse Phase II | L27: Kawasan Industri Terpadu Indonesia China (KITIC) Kav. 20, Cikarang, West Java | M27: Cikarang Logistic Center | N27: 2016 | R27: 1 | T27: 2061766435 | U27: =+T27/V27 -> 8590693.5 | V27: 240 | W27: 108 | X27: =+AC27/U27 -> 12 | Y27: =+W27+X27 -> 120 | Z27: =+V27-Y27 -> 120 | AA27: 9.277949e+08 | AB27: 1.1339715e+09 | AC27: =SUM(AD27:AO27) -> 1.0308832e+08 | AD27: 8590693.5 | AE27: 8590693.5 | AF27: 8590693.5 | AG27: 8590693.5 | AH27: 8590693.5 | AI27: 8590693.5 | AJ27: 8590693.5 | AK27: 8590693.5 | AL27: 8590693.5 | AM27: 8590693.5 | AN27: 8590693.5 | AO27: 8590693.5 | AP27: =+AA27+AC27 -> 1.0308832e+09 | AQ27: =IF(AS27=$AS$24,((T27-AP27)*0),T27-AP27) -> 1.0308832e+09 | AV27: Ok | AW27: =IFERROR(VLOOKUP(G27,'[70]Detail Deprec_202508'!$D$33:$I$357,6,FALSE),0) -> 8590693.5 | AX27: =AW27-AK27 -> 0.0008333344
A28: 3 | B28: CLC | C28: CLCWH | D28: 152 | E28: WH2 | F28: CLC131-002 | G28: BLD000064 | H28: 42387 | I28: Building | J28: 05 | K28: Lobby & Office Phase 2 | L28: Kawasan Industri Terpadu Indonesia China (KITIC) Kav. 20, Cikarang, West Java | M28: Cikarang Logistic Center | N28: 2016 | R28: 1 | T28: 5000000000 | U28: =+T28/V28 -> 20833333 | V28: 240 | W28: 108 | X28: =+AC28/U28 -> 12 | Y28: =+W28+X28 -> 120 | Z28: =+V28-Y28 -> 120 | AA28: 2.25e+09 | AB28: 2.75e+09 | AC28: =SUM(AD28:AO28) -> 2.5e+08 | AD28: 20833333 | AE28: 20833333 | AF28: 20833333 | AG28: 20833333 | AH28: 20833333 | AI28: 20833333 | AJ28: 20833333 | AK28: 20833333 | AL28: 20833333 | AM28: 20833333 | AN28: 20833333 | AO28: 20833333 | AP28: =+AA28+AC28 -> 2.5e+09 | AQ28: =IF(AS28=$AS$24,((T28-AP28)*0),T28-AP28) -> 2.5e+09 | AV28: Ok | AW28: =IFERROR(VLOOKUP(G28,'[70]Detail Deprec_202508'!$D$33:$I$357,6,FALSE),0) -> 20833333 | AX28: =AW28-AK28 -> -0.0033333339
A29: 4 | B29: CLC | C29: CLCWH | D29: 152 | E29: WH2 | F29: CLC131-002 | G29: BLD000065 | H29: 42387 | I29: Building | J29: 05 | K29: Warehouse Phase 2 Floor 2 | L29: Kawasan Industri Terpadu Indonesia China (KITIC) Kav. 20, Cikarang, West Java | M29: Cikarang Logistic Center | N29: 2016 | R29: 1 | T29: 44455000000 | U29: =+T29/V29 -> 1.8522917e+08 | V29: 240 | W29: 108 | X29: =+AC29/U29 -> 12 | Y29: =+W29+X29 -> 120 | Z29: =+V29-Y29 -> 120 | AA29: 2.000475e+10 | AB29: 2.445025e+10 | AC29: =SUM(AD29:AO29) -> 2.22275e+09 | AD29: 1.8522917e+08 | AE29: 1.8522917e+08 | AF29: 1.8522917e+08 | AG29: 1.8522917e+08 | AH29: 1.8522917e+08 | AI29: 1.8522917e+08 | AJ29: 1.8522917e+08 | AK29: 1.8522917e+08 | AL29: 1.8522917e+08 | AM29: 1.8522917e+08 | AN29: 1.8522917e+08 | AO29: 1.8522917e+08 | AP29: =+AA29+AC29 -> 2.22275e+10 | AQ29: =IF(AS29=$AS$24,((T29-AP29)*0),T29-AP29) -> 2.22275e+10 | AV29: Ok | AW29: =IFERROR(VLOOKUP(G29,'[70]Detail Deprec_202508'!$D$33:$I$357,6,FALSE),0) -> 1.8522917e+08 | AX29: =AW29-AK29 -> 0.0033333302
A30: 5 | B30: CLC | C30: CLCWH | D30: 152 | E30: WH2 | F30: CLC131-002 | G30: BLD000066 | H30: 42387 | I30: Building | J30: 05 | K30: Warehouse Phase 2 Floor 1 | L30: Kawasan Industri Terpadu Indonesia China (KITIC) Kav. 20, Cikarang, West Java | M30: Cikarang Logistic Center | N30: 2016 | R30: 1 | T30: 49455000000 | U30: =+T30/V30 -> 206062500 | V30: 240 | W30: 108 | X30: =+AC30/U30 -> 12 | Y30: =+W30+X30 -> 120 | Z30: =+V30-Y30 -> 120 | AA30: 22254750000 | AB30: 27200250000 | AC30: =SUM(AD30:AO30) -> 2472750000 | AD30: 206062500 | AE30: 206062500 | AF30: 206062500 | AG30: 206062500 | AH30: 206062500 | AI30: 206062500 | AJ30: 206062500 | AK30: 206062500 | AL30: 206062500 | AM30: 206062500 | AN30: 206062500 | AO30: 206062500 | AP30: =+AA30+AC30 -> 24727500000 | AQ30: =IF(AS30=$AS$24,((T30-AP30)*0),T30-AP30) -> 24727500000 | AV30: Ok | AW30: =IFERROR(VLOOKUP(G30,'[70]Detail Deprec_202508'!$D$33:$I$357,6,FALSE),0) -> 206062500 | AX30: =AW30-AK30 -> 0
A31: 6 | B31: CLC | C31: CLCWH | D31: 152 | E31: WH2 | F31: CLC131-002 | G31: BLD000067 | H31: 42387 | I31: Building | J31: 05 | K31: Cold Room Area Phase 2 | L31: Kawasan Industri Terpadu Indonesia China (KITIC) Kav. 20, Cikarang, West Java | M31: Cikarang Logistic Center | N31: 2016 | R31: 1 | T31: 35325000000 | U31: =+T31/V31 -> 147187500 | V31: 240 | W31: 108 | X31: =+AC31/U31 -> 12 | Y31: =+W31+X31 -> 120 | Z31: =+V31-Y31 -> 120 | AA31: 15896250000 | AB31: 19428750000 | AC31: =SUM(AD31:AO31) -> 1766250000 | AD31: 147187500 | AE31: 147187500 | AF31: 147187500 | AG31: 147187500 | AH31: 147187500 | AI31: 147187500 | AJ31: 147187500 | AK31: 147187500 | AL31: 147187500 | AM31: 147187500 | AN31: 147187500 | AO31: 147187500 | AP31: =+AA31+AC31 -> 17662500000 | AQ31: =IF(AS31=$AS$24,((T31-AP31)*0),T31-AP31) -> 17662500000 | AV31: Ok | AW31: =IFERROR(VLOOKUP(G31,'[70]Detail Deprec_202508'!$D$33:$I$357,6,FALSE),0) -> 147187500 | AX31: =AW31-AK31 -> 0
A32: 7 | B32: CLC | C32: CLCWH | D32: 152 | E32: WH2 | F32: CLC131-002 | G32: BLD000068 | H32: 42387 | I32: Building | J32: 05 | K32: Cargo Lifter Phase 2 | L32: Kawasan Industri Terpadu Indonesia China (KITIC) Kav. 20, Cikarang, West Java | M32: Cikarang Logistic Center | N32: 2016 | R32: 1 | S32: 271320 | T32: 3375220800 | U32: =+T32/V32 -> 14063420 | V32: 240 | W32: 108 | X32: =+AC32/U32 -> 12 | Y32: =+W32+X32 -> 120 | Z32: =+V32-Y32 -> 120 | AA32: 1518849360 | AB32: 1856371440 | AC32: =SUM(AD32:AO32) -> 168761040 | AD32: 14063420 | AE32: 14063420 | AF32: 14063420 | AG32: 14063420 | AH32: 14063420 | AI32: 14063420 | AJ32: 14063420 | AK32: 14063420 | AL32: 14063420 | AM32: 14063420 | AN32: 14063420 | AO32: 14063420 | AP32: =+AA32+AC32 -> 1687610400 | AQ32: =IF(AS32=$AS$24,((T32-AP32)*0),T32-AP32) -> 1687610400 | AV32: Ok | AW32: =IFERROR(VLOOKUP(G32,'[70]Detail Deprec_202508'!$D$33:$I$357,6,FALSE),0) -> 14063420 | AX32: =AW32-AK32 -> 0
A33: 8 | B33: CLC | C33: CLCWH | D33: 152 | E33: WH2 | F33: CLC131-003 | G33: BLD000069 | H33: 42387 | I33: Building | J33: 05 | K33: Cargo Lifter Phase 2 | L33: Kawasan Industri Terpadu Indonesia China (KITIC) Kav. 20, Cikarang, West Java | M33: Cikarang Logistic Center | N33: 2016 | R33: 1 | S33: 271320 | T33: 3549950880 | U33: =+T33/V33 -> 14791462 | V33: 240 | W33: 108 | X33: =+AC33/U33 -> 12 | Y33: =+W33+X33 -> 120 | Z33: =+V33-Y33 -> 120 | AA33: 1597477896 | AB33: 1952472984 | AC33: =SUM(AD33:AO33) -> 177497544 | AD33: 14791462 | AE33: 14791462 | AF33: 14791462 | AG33: 14791462 | AH33: 14791462 | AI33: 14791462 | AJ33: 14791462 | AK33: 14791462 | AL33: 14791462 | AM33: 14791462 | AN33: 14791462 | AO33: 14791462 | AP33: =+AA33+AC33 -> 1774975440 | AQ33: =IF(AS33=$AS$24,((T33-AP33)*0),T33-AP33) -> 1774975440 | AV33: Ok | AW33: =IFERROR(VLOOKUP(G33,'[70]Detail Deprec_202508'!$D$33:$I$357,6,FALSE),0) -> 14791462 | AX33: =AW33-AK33 -> 0
A34: 9 | B34: CLC | C34: CLCWH | D34: 152 | E34: WH2 | F34: CLC131-003 | G34: BLD000070 | H34: 42387 | I34: Building | J34: 05 | K34: Canopy Area Phase 2 | L34: Kawasan Industri Terpadu Indonesia China (KITIC) Kav. 20, Cikarang, West Java | M34: Cikarang Logistic Center | N34: 2016 | R34: 1 | S34: 193800 | T34: 2612617800 | U34: =+T34/V34 -> 10885908 | V34: 240 | W34: 108 | X34: =+AC34/U34 -> 12 | Y34: =+W34+X34 -> 120 | Z34: =+V34-Y34 -> 120 | AA34: 1175678010 | AB34: 1436939790 | AC34: =SUM(AD34:AO34) -> 130630890 | AD34: 10885908 | AE34: 10885908 | AF34: 10885908 | AG34: 10885908 | AH34: 10885908 | AI34: 10885908 | AJ34: 10885908 | AK34: 10885908 | AL34: 10885908 | AM34: 10885908 | AN34: 10885908 | AO34: 10885908 | AP34: =+AA34+AC34 -> 1306308900 | AQ34: =IF(AS34=$AS$24,((T34-AP34)*0),T34-AP34) -> 1306308900 | AV34: Ok | AW34: =IFERROR(VLOOKUP(G34,'[70]Detail Deprec_202508'!$D$33:$I$357,6,FALSE),0) -> 10885908 | AX34: =AW34-AK34 -> 0
A35: 10 | B35: CLC | C35: CLCWH | D35: 152 | E35: WH2 | F35: CLC131-003 | G35: BLD000071 | H35: 42387 | I35: Building | J35: 05 | K35: Omni Lifter Phase 2 | L35: Kawasan Industri Terpadu Indonesia China (KITIC) Kav. 20, Cikarang, West Java | M35: Cikarang Logistic Center | N35: 2016 | R35: 1 | T35: 7065000000 | U35: =+T35/V35 -> 29437500 | V35: 240 | W35: 108 | X35: =+AC35/U35 -> 12 | Y35: =+W35+X35 -> 120 | Z35: =+V35-Y35 -> 120 | AA35: 3179250000 | AB35: 3885750000 | AC35: =SUM(AD35:AO35) -> 353250000 | AD35: 29437500 | AE35: 29437500 | AF35: 29437500 | AG35: 29437500 | AH35: 29437500 | AI35: 29437500 | AJ35: 29437500 | AK35: 29437500 | AL35: 29437500 | AM35: 29437500 | AN35: 29437500 | AO35: 29437500 | AP35: =+AA35+AC35 -> 3532500000 | AQ35: =IF(AS35=$AS$24,((T35-AP35)*0),T35-AP35) -> 3532500000 | AV35: Ok | AW35: =IFERROR(VLOOKUP(G35,'[70]Detail Deprec_202508'!$D$33:$I$357,6,FALSE),0) -> 29437500 | AX35: =AW35-AK35 -> 0
A36: 11 | B36: CLC | C36: CLCWH | D36: 152 | E36: WH2 | F36: CLC131-003 | G36: BLD000072 | H36: 42387 | I36: Building | J36: 05 | K36: Omni Lifter Phase 2 | L36: Kawasan Industri Terpadu Indonesia China (KITIC) Kav. 20, Cikarang, West Java | M36: Cikarang Logistic Center | N36: 2016 | R36: 1 | S36: 38760 | T36: 534694200 | U36: =+T36/V36 -> 2227892.5 | V36: 240 | W36: 108 | X36: =+AC36/U36 -> 12 | Y36: =+W36+X36 -> 120 | Z36: =+V36-Y36 -> 120 | AA36: 240612390 | AB36: 294081810 | AC36: =SUM(AD36:AO36) -> 26734710 | AD36: 2227892.5 | AE36: 2227892.5 | AF36: 2227892.5 | AG36: 2227892.5 | AH36: 2227892.5 | AI36: 2227892.5 | AJ36: 2227892.5 | AK36: 2227892.5 | AL36: 2227892.5 | AM36: 2227892.5 | AN36: 2227892.5 | AO36: 2227892.5 | AP36: =+AA36+AC36 -> 267347100 | AQ36: =IF(AS36=$AS$24,((T36-AP36)*0),T36-AP36) -> 267347100 | AV36: Ok | AW36: =IFERROR(VLOOKUP(G36,'[70]Detail Deprec_202508'!$D$33:$I$357,6,FALSE),0) -> 2227892.5 | AX36: =AW36-AK36 -> 0
A37: 12 | B37: CLC | C37: CLCWH | D37: 152 | E37: WH2 | F37: CLC131-003 | G37: BLD000073 | H37: 42387 | I37: Building | J37: 05 | K37: Mezzanine Area Phase 2 | L37: Kawasan Industri Terpadu Indonesia China (KITIC) Kav. 20, Cikarang, West Java | M37: Cikarang Logistic Center | N37: 2016 | R37: 1 | T37: 1338483845 | U37: =+T37/V37 -> 5577016 | V37: 240 | W37: 108 | X37: =+AC37/U37 -> 12 | Y37: =+W37+X37 -> 120 | Z37: =+V37-Y37 -> 120 | AA37: 6.0231773e+08 | AB37: 7.3616611e+08 | AC37: =SUM(AD37:AO37) -> 66924192 | AD37: 5577016 | AE37: 5577016 | AF37: 5577016 | AG37: 5577016 | AH37: 5577016 | AI37: 5577016 | AJ37: 5577016 | AK37: 5577016 | AL37: 5577016 | AM37: 5577016 | AN37: 5577016 | AO37: 5577016 | AP37: =+AA37+AC37 -> 6.6924192e+08 | AQ37: =IF(AS37=$AS$24,((T37-AP37)*0),T37-AP37) -> 6.6924192e+08 | AV37: Ok | AW37: =IFERROR(VLOOKUP(G37,'[70]Detail Deprec_202508'!$D$33:$I$357,6,FALSE),0) -> 5577016 | AX37: =AW37-AK37 -> -0.00083333347
A38: 13 | B38: CLC | C38: CLCWH | D38: 152 | E38: WH2 | F38: CLC131-005 | G38: BLD000076 | H38: 43830 | I38: Building | J38: 007-12 | K38: Roof for Motorcycle Parking Area (80%) | L38: SII JKC | M38: KITIC Office | N38: 2019 | R38: 1 | T38: 177294305 | U38: =+T38/V38 -> 738726.27 | V38: 240 | W38: 61 | X38: =+AC38/U38 -> 12 | Y38: =+W38+X38 -> 73 | Z38: =+V38-Y38 -> 167 | AA38: 45062303 | AB38: 1.32232e+08 | AC38: =SUM(AD38:AO38) -> 8864715.2 | AD38: 738726.27 | AE38: 738726.27 | AF38: 738726.27 | AG38: 738726.27 | AH38: 738726.27 | AI38: 738726.27 | AJ38: 738726.27 | AK38: 738726.27 | AL38: 738726.27 | AM38: 738726.27 | AN38: 738726.27 | AO38: 738726.27 | AP38: =+AA38+AC38 -> 53927018 | AQ38: =IF(AS38=$AS$24,((T38-AP38)*0),T38-AP38) -> 1.2336729e+08 | AV38: Ok | AW38: =IFERROR(VLOOKUP(G38,'[70]Detail Deprec_202508'!$D$33:$I$357,6,FALSE),0) -> 738726.27 | AX38: =AW38-AK38 -> -0.00083333335
A39: 14 | B39: CLC | C39: CLCWH | D39: 153 | E39: WH1 | F39: CLC133-001 | G39: STR000005 | H39: 41639 | I39: Structures | J39: 2005 | K39: Security system & installation | L39: SECOM Indonesia | M39: Cikarang Warehouse & Office | N39: 2013 | R39: 1 | S39: 4082 | T39: 48890114 | U39: =+T39/V39 -> 814835.23 | V39: 60 | W39: 60 | X39: =+AC39/U39 -> 0 | Y39: =+W39+X39 -> 60 | Z39: =+V39-Y39 -> 0 | AA39: 48890114 | AB39: 1.4901161e-08 | AC39: =SUM(AD39:AL39) -> 0 | AP39: =+AA39+AC39 -> 48890114 | AQ39: =IF(AS39=$AS$24,((T39-AP39)*0),T39-AP39) -> 1.4901161e-08 | AV39: Ok | AW39: =IFERROR(VLOOKUP(G39,'[70]Detail Deprec_202508'!$D$33:$I$357,6,FALSE),0) -> 0 | AX39: =AW39-AK39 -> 0
A40: =+A39+1 -> 15 | B40: CLC | C40: CLCWH | D40: 153 | E40: WH1 | F40: CLC133-002 | G40: STR000006 | H40: 41639 | I40: Structures | J40: 2007 | K40: CCTV system WH 1 | L40: SECOM Indonesia | M40: Cikarang Warehouse & Office | N40: 2013 | R40: 1 | S40: 40583.96 | T40: 4.8607409e+08 | U40: =+T40/V40 -> 8101234.8 | V40: 60 | W40: 60 | X40: =+AC40/U40 -> 0 | Y40: =+W40+X40 -> 60 | Z40: =+V40-Y40 -> 0 | AA40: 4.8607409e+08 | AB40: -1.1920929e-07 | AC40: =SUM(AD40:AL40) -> 0 | AP40: =+AA40+AC40 -> 4.8607409e+08 | AQ40: =IF(AS40=$AS$24,((T40-AP40)*0),T40-AP40) -> -1.1920929e-07 | AV40: Ok | AW40: =IFERROR(VLOOKUP(G40,'[70]Detail Deprec_202508'!$D$33:$I$357,6,FALSE),0) -> 0 | AX40: =AW40-AK40 -> 0
A41: =+A40+1 -> 16 | B41: CLC | C41: CLCWH | D41: 153 | E41: WH1 | F41: CLC133-003 | G41: STR000007 | H41: 41639 | I41: Structures | J41: 2008 | K41: Access control | L41: SECOM Indonesia | M41: Cikarang Warehouse & Office | N41: 2013 | R41: 1 | S41: 4246 | T41: 50854342 | U41: =+T41/V41 -> 847572.37 | V41: 60 | W41: 60 | X41: =+AC41/U41 -> 0 | Y41: =+W41+X41 -> 60 | Z41: =+V41-Y41 -> 0 | AA41: 50854342 | AB41: -2.2351742e-08 | AC41: =SUM(AD41:AL41) -> 0 | AP41: =+AA41+AC41 -> 50854342 | AQ41: =IF(AS41=$AS$24,((T41-AP41)*0),T41-AP41) -> -2.2351742e-08 | AV41: Ok | AW41: =IFERROR(VLOOKUP(G41,'[70]Detail Deprec_202508'!$D$33:$I$357,6,FALSE),0) -> 0 | AX41: =AW41-AK41 -> 0
A42: =+A41+1 -> 17 | B42: CLC | C42: CLCWH | D42: 153 | E42: WH1 | F42: CLC133-004 | G42: STR000008 | H42: 41639 | I42: Structures | J42: 2011 | K42: Security system & installation | L42: SECOM Indonesia | M42: Cikarang Warehouse & Office | N42: 2013 | R42: 1 | S42: 519 | T42: 6216063 | U42: =+T42/V42 -> 103601.05 | V42: 60 | W42: 60 | X42: =+AC42/U42 -> 0 | Y42: =+W42+X42 -> 60 | Z42: =+V42-Y42 -> 0 | AA42: 6216063 | AB42: -1.8626451e-09 | AC42: =SUM(AD42:AL42) -> 0 | AP42: =+AA42+AC42 -> 6216063 | AQ42: =IF(AS42=$AS$24,((T42-AP42)*0),T42-AP42) -> -1.8626451e-09 | AV42: Ok | AW42: =IFERROR(VLOOKUP(G42,'[70]Detail Deprec_202508'!$D$33:$I$357,6,FALSE),0) -> 0 | AX42: =AW42-AK42 -> 0
A43: =+A42+1 -> 18 | B43: CLC | C43: CLCWH | D43: 153 | E43: WH1 | F43: CLC133-026 | G43: STR000013 | H43: 41759 | I43: Structures | J43: 64 | K43: Wifi Terminal DG | L43: Dangerous Room (KDDI Indonesia) | N43: 2014 | R43: 1 | T43: 156382893 | U43: =+T43/V43 -> 2606381.5 | V43: 60 | W43: 60 | X43: =+AC43/U43 -> 0 | Y43: =+W43+X43 -> 60 | Z43: =+V43-Y43 -> 0 | AA43: 156382893 | AB43: 0 | AC43: =SUM(AD43:AL43) -> 0 | AP43: =+AA43+AC43 -> 156382893 | AQ43: =IF(AS43=$AS$24,((T43-AP43)*0),T43-AP43) -> 0 | AV43: Ok | AW43: =IFERROR(VLOOKUP(G43,'[70]Detail Deprec_202508'!$D$33:$I$357,6,FALSE),0) -> 0 | AX43: =AW43-AK43 -> 0
...

Sheet FA_2026
A1: PT. SANKYU INDONESIA INTERNATIONAL
A2: LIST OF FIXED ASSETS AND DEPRECIATION SCHEDULE
A3: 46387
F5: CATEGORY | G5: JANUARY | H5: FEBRUARY | I5: MARCH | J5: APRIL | K5: MAY | L5: JUNE | M5: JULY | N5: AUGUST | O5: SEPTEMBER | P5: OCTOBER | Q5: NOVEMBER | R5: DECEMBER | S5: TOTAL/YEAR
E6: Warehouse 1 | F6: WH1 | G6: =SUMIF($E$25:$E$281,F6,$AD$25:$AD$281) -> 3.034665e+08 | H6: =SUMIF($E$25:$E$282,F6,$AE$25:$AE$282) -> 3.034665e+08 | I6: =SUMIF($E$25:$E$282,F6,$AF$25:$AF$282) -> 3.034665e+08 | J6: =SUMIF($E$25:$E$282,F6,$AG$25:$AG$282) -> 3.034665e+08 | K6: =SUMIF($E$25:$E$282,F6,$AH$25:$AH$282) -> 3.034665e+08 | L6: =SUMIF($E$25:$E$282,F6,$AI$25:$AI$281) -> 3.034665e+08 | M6: =SUMIF($E$25:$E$282,F6,$AJ$25:$AJ$282) -> 3.034665e+08 | N6: =SUMIF($E$25:$E$281,F6,$AK$25:$AK$281) -> 3.034665e+08 | O6: =SUMIF($E$25:$E$281,F6,$AL$25:$AL$281) -> 3.034665e+08 | P6: =SUMIF($E$25:$E$281,F6,$AM$25:$AM$281) -> 3.034665e+08 | Q6: =SUMIF($E$25:$E$281,F6,$AN$25:$AN$281) -> 3.034665e+08 | R6: =SUMIF($E$25:$E$281,F6,$AO$25:$AO$281) -> 3.034665e+08 | S6: =SUM(G6:R6) -> 3.641598e+09
E7: Warehouse 2 | F7: WH2 | G7: =SUMIF($E$25:$E$281,F7,$AD$25:$AD$281) -> 6.5201362e+08 | H7: =SUMIF($E$25:$E$281,F7,$AE$25:$AE$281) -> 6.5201362e+08 | I7: =SUMIF($E$25:$E$281,F7,$AF$25:$AF$281) -> 6.5201362e+08 | J7: =SUMIF($E$25:$E$281,F7,$AG$25:$AG$281) -> 6.5201362e+08 | K7: =SUMIF($E$25:$E$281,F7,$AH$25:$AH$281) -> 6.5201362e+08 | L7: =SUMIF($E$25:$E$281,F7,$AI$25:$AI$281) -> 6.5201362e+08 | M7: =SUMIF($E$25:$E$281,F7,$AJ$25:$AJ$281) -> 6.5201362e+08 | N7: =SUMIF($E$25:$E$281,F7,$AK$25:$AK$281) -> 6.5201362e+08 | O7: =SUMIF($E$25:$E$281,F7,$AL$25:$AL$281) -> 6.5201362e+08 | P7: =SUMIF($E$25:$E$281,F7,$AM$25:$AM$281) -> 6.5201362e+08 | Q7: =SUMIF($E$25:$E$281,F7,$AN$25:$AN$281) -> 6.5201362e+08 | R7: =SUMIF($E$25:$E$281,F7,$AO$25:$AO$281) -> 6.5201362e+08 | S7: =SUM(G7:R7) -> 7.8241634e+09
E8: Transport | F8: TRP | G8: =SUMIF($E$25:$E$282,F8,$AD$25:$AD$281) -> 67290240 | H8: =SUMIF($E$25:$E$282,F8,$AE$25:$AE$281) -> 67290240 | I8: =SUMIF($E$25:$E$281,F8,$AF$25:$AF$282) -> 67290240 | J8: =SUMIF($E$25:$E$281,F8,$AG$25:$AG$281) -> 67290240 | K8: =SUMIF($E$25:$E$281,F8,$AH$25:$AH$281) -> 67290240 | L8: =SUMIF($E$25:$E$281,F8,$AI$25:$AI$281) -> 67290240 | M8: =SUMIF($E$25:$E$281,F8,$AJ$25:$AJ$281) -> 67290240 | N8: =SUMIF($E$25:$E$281,F8,$AK$25:$AK$281) -> 67290240 | O8: =SUMIF($E$25:$E$281,F8,$AL$25:$AL$281) -> 67290240 | P8: =SUMIF($E$25:$E$281,F8,$AM$25:$AM$281) -> 67290240 | Q8: =SUMIF($E$25:$E$281,F8,$AN$25:$AN$281) -> 67290240 | R8: =SUMIF($E$25:$E$281,F8,$AO$25:$AO$281) -> 67290240 | S8: =SUM(G8:R8) -> 8.0748288e+08
E9: Bali | F9: BALI | G9: =SUMIF($E$25:$E$282,F9,$AD$25:$AD$281) -> 1.1998584e+08 | H9: =SUMIF($E$25:$E$282,F9,$AE$25:$AE$281) -> 1.1998584e+08 | I9: =SUMIF($E$25:$E$281,F9,$AF$25:$AF$282) -> 1.1998584e+08 | J9: =SUMIF($E$25:$E$281,F9,$AG$25:$AG$281) -> 1.1998584e+08 | K9: =SUMIF($E$25:$E$281,F9,$AH$25:$AH$281) -> 1.1998584e+08 | L9: =SUMIF($E$25:$E$281,F9,$AI$25:$AI$281) -> 1.1998584e+08 | M9: =SUMIF($E$25:$E$281,F9,$AJ$25:$AJ$281) -> 1.1998584e+08 | N9: =SUMIF($E$25:$E$281,F9,$AK$25:$AK$281) -> 1.1998584e+08 | O9: =SUMIF($E$25:$E$281,F9,$AL$25:$AL$281) -> 1.1998584e+08 | P9: =SUMIF($E$25:$E$281,F9,$AM$25:$AM$281) -> 1.1998584e+08 | Q9: =SUMIF($E$25:$E$281,F9,$AN$25:$AN$281) -> 1.1998584e+08 | R9: =SUMIF($E$25:$E$281,F9,$AO$25:$AO$281) -> 1.1998584e+08 | S9: =SUM(G9:R9) -> 1439830051
E10: Medan | F10: MDN | G10: =SUMIF($E$25:$E$282,F10,$AD$25:$AD$281) -> 0 | H10: =SUMIF($E$25:$E$282,F10,$AE$25:$AE$281) -> 0 | I10: =SUMIF($E$25:$E$281,F10,$AF$25:$AF$282) -> 0 | J10: =SUMIF($E$25:$E$281,F10,$AG$25:$AG$281) -> 0 | K10: =SUMIF($E$25:$E$281,F10,$AH$25:$AH$281) -> 0 | L10: =SUMIF($E$25:$E$281,F10,$AI$25:$AI$281) -> 0 | M10: =SUMIF($E$25:$E$281,F10,$AJ$25:$AJ$281) -> 0 | N10: =SUMIF($E$25:$E$281,F10,$AK$25:$AK$281) -> 0 | O10: =SUMIF($E$25:$E$281,F10,$AL$25:$AL$281) -> 0 | P10: =SUMIF($E$25:$E$281,F10,$AM$25:$AM$281) -> 0 | Q10: =SUMIF($E$25:$E$281,F10,$AN$25:$AN$281) -> 0 | R10: =SUMIF($E$25:$E$281,F10,$AO$25:$AO$281) -> 0 | S10: =SUM(G10:R10) -> 0
E11: Palembang | F11: PBG | G11: =SUMIF($E$25:$E$282,F11,$AD$25:$AD$281) -> 13333333 | H11: =SUMIF($E$25:$E$282,F11,$AE$25:$AE$281) -> 13333333 | I11: =SUMIF($E$25:$E$281,F11,$AF$25:$AF$282) -> 13333333 | J11: =SUMIF($E$25:$E$281,F11,$AG$25:$AG$281) -> 13333333 | K11: =SUMIF($E$25:$E$281,F11,$AH$25:$AH$281) -> 0 | L11: =SUMIF($E$25:$E$281,F11,$AI$25:$AI$281) -> 0 | M11: =SUMIF($E$25:$E$281,F11,$AJ$25:$AJ$281) -> 0 | N11: =SUMIF($E$25:$E$281,F11,$AK$25:$AK$281) -> 0 | O11: =SUMIF($E$25:$E$281,F11,$AL$25:$AL$281) -> 0 | P11: =SUMIF($E$25:$E$281,F11,$AM$25:$AM$281) -> 0 | Q11: =SUMIF($E$25:$E$281,F11,$AN$25:$AN$281) -> 0 | R11: =SUMIF($E$25:$E$281,F11,$AO$25:$AO$281) -> 0 | S11: =SUM(G11:R11) -> 53333332
E12: Makassar | F12: MKS | G12: =SUMIF($E$25:$E$282,F12,$AD$25:$AD$281) -> 0 | H12: =SUMIF($E$25:$E$282,F12,$AE$25:$AE$281) -> 0 | I12: =SUMIF($E$25:$E$281,F12,$AF$25:$AF$282) -> 0 | J12: =SUMIF($E$25:$E$281,F12,$AG$25:$AG$281) -> 0 | K12: =SUMIF($E$25:$E$281,F12,$AH$25:$AH$281) -> 0 | L12: =SUMIF($E$25:$E$281,F12,$AI$25:$AI$281) -> 0 | M12: =SUMIF($E$25:$E$281,F12,$AJ$25:$AJ$281) -> 0 | N12: =SUMIF($E$25:$E$281,F12,$AK$25:$AK$281) -> 0 | O12: =SUMIF($E$25:$E$281,F12,$AL$25:$AL$281) -> 0 | P12: =SUMIF($E$25:$E$281,F12,$AM$25:$AM$281) -> 0 | Q12: =SUMIF($E$25:$E$281,F12,$AN$25:$AN$281) -> 0 | R12: =SUMIF($E$25:$E$281,F12,$AO$25:$AO$281) -> 0 | S12: =SUM(G12:R12) -> 0
E13: Surabaya | F13: SBY | G13: =SUMIF($E$25:$E$282,F13,$AD$25:$AD$281) -> 0 | H13: =SUMIF($E$25:$E$282,F13,$AE$25:$AE$281) -> 0 | I13: =SUMIF($E$25:$E$281,F13,$AF$25:$AF$282) -> 0 | J13: =SUMIF($E$25:$E$281,F13,$AG$25:$AG$281) -> 0 | K13: =SUMIF($E$25:$E$281,F13,$AH$25:$AH$281) -> 0 | L13: =SUMIF($E$25:$E$281,F13,$AI$25:$AI$281) -> 0 | M13: =SUMIF($E$25:$E$281,F13,$AJ$25:$AJ$281) -> 0 | N13: =SUMIF($E$25:$E$281,F13,$AK$25:$AK$281) -> 0 | O13: =SUMIF($E$25:$E$281,F13,$AL$25:$AL$281) -> 0 | P13: =SUMIF($E$25:$E$281,F13,$AM$25:$AM$281) -> 0 | Q13: =SUMIF($E$25:$E$281,F13,$AN$25:$AN$281) -> 0 | R13: =SUMIF($E$25:$E$281,F13,$AO$25:$AO$281) -> 0 | S13: =SUM(G13:R13) -> 0
E14: Forklift, Shuttle Car, Equipment, Nestainer Rack | F14: OTHERS | G14: =SUMIF($E$25:$E$282,F14,$AD$25:$AD$281) -> 1.1746952e+08 | H14: =SUMIF($E$25:$E$282,F14,$AE$25:$AE$281) -> 1.1746952e+08 | I14: =SUMIF($E$25:$E$281,F14,$AF$25:$AF$282) -> 1.1650695e+08 | J14: =SUMIF($E$25:$E$281,F14,$AG$25:$AG$281) -> 1.1650695e+08 | K14: =SUMIF($E$25:$E$281,F14,$AH$25:$AH$281) -> 1.1617695e+08 | L14: =SUMIF($E$25:$E$281,F14,$AI$25:$AI$281) -> 1.1056028e+08 | M14: =SUMIF($E$25:$E$281,F14,$AJ$25:$AJ$281) -> 1.1056028e+08 | N14: =SUMIF($E$25:$E$281,F14,$AK$25:$AK$281) -> 1.1056028e+08 | O14: =SUMIF($E$25:$E$281,F14,$AL$25:$AL$281) -> 1.1056028e+08 | P14: =SUMIF($E$25:$E$281,F14,$AM$25:$AM$281) -> 1.1056028e+08 | Q14: =SUMIF($E$25:$E$281,F14,$AN$25:$AN$281) -> 1.1056028e+08 | R14: =SUMIF($E$25:$E$281,F14,$AO$25:$AO$281) -> 1.1056028e+08 | S14: =SUM(G14:R14) -> 1.3580519e+09
G15: =SUBTOTAL(9,G6:G14) -> 1.273559e+09 | H15: =SUBTOTAL(9,H6:H14) -> 1.273559e+09 | I15: =SUBTOTAL(9,I6:I14) -> 1.2725965e+09 | J15: =SUBTOTAL(9,J6:J14) -> 1.2725965e+09 | K15: =SUBTOTAL(9,K6:K14) -> 1.2589331e+09 | L15: =SUBTOTAL(9,L6:L14) -> 1.2533165e+09 | M15: =SUBTOTAL(9,M6:M14) -> 1.2533165e+09 | N15: =SUBTOTAL(9,N6:N14) -> 1.2533165e+09 | ... S15: =SUBTOTAL(9,S6:S14) -> 1.512446e+10
F17: SITE | G17: JANUARY | H17: FEBRUARY | I17: MARCH | J17: APRIL | K17: MAY | L17: JUNE | M17: JULY | N17: AUGUST | O17: SEPTEMBER | P17: OCTOBER | Q17: NOVEMBER | R17: DECEMBER | S17: TOTAL/YEAR
F18: CLCWH | G18: =SUMIF($C$25:$C$281,F18,$AD$25:$AD$281) -> 1.0870496e+09 | H18: =SUMIF($C$25:$C$281,F18,$AE$25:$AE$281) -> 1.0870496e+09 | I18: =SUMIF($C$25:$C$281,F18,$AF$25:$AF$281) -> 1.0860871e+09 | J18: =SUMIF($C$25:$C$281,F18,$AG$25:$AG$281) -> 1.0860871e+09 | K18: =SUMIF($C$25:$C$281,F18,$AH$25:$AH$281) -> 1.0857571e+09 | L18: =SUMIF($C$25:$C$281,F18,$AI$25:$AI$281) -> 1.0801404e+09 | M18: =SUMIF($C$25:$C$281,F18,$AJ$25:$AJ$281) -> 1.0801404e+09 | N18: =SUMIF($C$25:$C$281,F18,$AK$25:$AK$281) -> 1.0801404e+09 | O18: =SUMIF($C$25:$C$281,F18,$AL$25:$AL$281) -> 1.0801404e+09 | P18: =SUMIF($C$25:$C$281,F18,$AM$25:$AM$281) -> 1.0801404e+09 | Q18: =SUMIF($C$25:$C$281,F18,$AN$25:$AN$281) -> 1.0801404e+09 | R18: =SUMIF($C$25:$C$281,F18,$AO$25:$AO$281) -> 1.0801404e+09 | S18: =SUM(G18:R18) -> 1.2993013e+10
F19: CLCOWH | G19: =SUMIF($C$25:$C$281,F19,$AD$25:$AD$281) -> 1.1921917e+08 | H19: =SUMIF($C$25:$C$281,F19,$AE$25:$AE$281) -> 1.1921917e+08 | I19: =SUMIF($C$25:$C$281,F19,$AF$25:$AF$281) -> 1.1921917e+08 | J19: =SUMIF($C$25:$C$281,F19,$AG$25:$AG$281) -> 1.1921917e+08 | K19: =SUMIF($C$25:$C$281,F19,$AH$25:$AH$281) -> 1.0588584e+08 | L19: =SUMIF($C$25:$C$281,F19,$AI$25:$AI$281) -> 1.0588584e+08 | M19: =SUMIF($C$25:$C$281,F19,$AJ$25:$AJ$281) -> 1.0588584e+08 | N19: =SUMIF($C$25:$C$281,F19,$AK$25:$AK$281) -> 1.0588584e+08 | O19: =SUMIF($C$25:$C$281,F19,$AL$25:$AL$281) -> 1.0588584e+08 | P19: =SUMIF($C$25:$C$281,F19,$AM$25:$AM$281) -> 1.0588584e+08 | Q19: =SUMIF($C$25:$C$281,F19,$AN$25:$AN$281) -> 1.0588584e+08 | R19: =SUMIF($C$25:$C$281,F19,$AO$25:$AO$281) -> 1.0588584e+08 | S19: =SUM(G19:R19) -> 1323963383
F20: CLCTRP | G20: =SUMIF($C$25:$C$281,F20,$AD$25:$AD$281) -> 67290240 | H20: =SUMIF($C$25:$C$281,F20,$AE$25:$AE$281) -> 67290240 | I20: =SUMIF($C$25:$C$281,F20,$AF$25:$AF$281) -> 67290240 | J20: =SUMIF($C$25:$C$281,F20,$AG$25:$AG$281) -> 67290240 | K20: =SUMIF($C$25:$C$281,F20,$AH$25:$AH$281) -> 67290240 | L20: =SUMIF($C$25:$C$281,F20,$AI$25:$AI$281) -> 67290240 | M20: =SUMIF($C$25:$C$281,F20,$AJ$25:$AJ$281) -> 67290240 | N20: =SUMIF($C$25:$C$281,F20,$AK$25:$AK$281) -> 67290240 | O20: =SUMIF($C$25:$C$281,F20,$AL$25:$AL$281) -> 67290240 | P20: =SUMIF($C$25:$C$281,F20,$AM$25:$AM$281) -> 67290240 | Q20: =SUMIF($C$25:$C$281,F20,$AN$25:$AN$281) -> 67290240 | R20: =SUMIF($C$25:$C$281,F20,$AO$25:$AO$281) -> 67290240 | S20: =SUM(G20:R20) -> 8.0748288e+08
G21: =SUM(G18:G20) -> 1.273559e+09 | H21: =SUM(H18:H20) -> 1.273559e+09 | I21: =SUM(I18:I20) -> 1.2725965e+09 | J21: =SUM(J18:J20) -> 1.2725965e+09 | K21: =SUM(K18:K20) -> 1.2589331e+09 | L21: =SUM(L18:L20) -> 1.2533165e+09 | M21: =SUM(M18:M20) -> 1.2533165e+09 | N21: =SUM(N18:N20) -> 1.2533165e+09 | ... S21: =SUM(S18:S20) -> 1.512446e+10
A23: No. | B23: Site/ Location | C23: Job | D23: Account | E23: Category | F23: Asset | G23: Fixed asset number | H23: Purchase Date | I23: Group | J23: Voucher | K23: Name of Fixed Asset | L23: Maker/Type/Location | M23: Capacity/Size/User | N23: Year | O23: Police | P23: Machine | Q23: Chasis | R23: Quantity | S23: Valas | T23: Purchase Price | U23: Monthly Depreciation | V23: Depreciation Period | AA23: Accumulated Depreciation | AB23: Net Book Value | AC23: Depreciation Expense Current | AD23: DEPRECIATION 2026 ( MONTHLY ) | AP23: Accumulated Depreciation | AQ23: Net Book Value | AR23: Status | AT23: Acquisition | AU23: Remark | AV23: Photo Status | AX23: Checker Name ( A ) | AZ23: Existing ( B ) | BB23: If Yes (Existing) ( C ) | BD23: If Not Used ( D ) | BF23: Sticker ( E )
D24: No. | F24: No. | G24: AX | J24: No. | O24: No. | P24: No. | Q24: No. | V24: Total | W24: Acc. 2025 | X24: Yearly 2026 | Y24: Until 2026 | Z24: Remain > 2027 | AA24: 46022 | AB24: 46022 | AC24: =+A3 -> 46387 | AD24: Jan | AE24: Feb | AF24: Mar | AG24: Apr | AH24: May | AI24: Jun | AJ24: Jul | AK24: Aug | AL24: Sep | AM24: Oct | AN24: Nov | AO24: Dec | AP24: =A3 -> 46387 | AQ24: =+AP24 -> 46387 | AR24: Additional | AS24: Disposals | AT24: Condition | AX24: Site | AY24: HO | AZ24: Yes | BA24: No | BB24: Still Used | BC24: Not Used | BD24: Repair | BE24: Disposals | BF24: Good | BG24: Bad
T25: a | U25: b=a:c | V25: c | W25: d=h:b | X25: e=j:b | Y25: f=d+e | Z25: g=c-f | AA25: l=h+j | AB25: m=a-l | AC25: j=total k (jAC-des) | AD25: k | AE25: k | AF25: k | AG25: k | AH25: k | AI25: k | AJ25: k | AK25: k | AL25: k | AM25: k | AN25: k | AO25: k | AP25: l=h+j | AQ25: m=a-l | AW25: Check
A26: 1 | B26: CLC | C26: CLCWH | D26: 152 | E26: WH1 | F26: CLC131-001 | G26: BLD000048 | H26: 41639 | I26: Building | J26: 111 | K26: Cikarang Warehouse and Office | L26: Kawasan Industri Terpadu Indonesia China (KITIC) Kav. 20, Cikarang, West Java | M26: Head Ofice & Cikarang Logistic | N26: 2013 | R26: 1 | T26: 7.1701319e+10 | U26: =+T26/V26 -> 2.987555e+08 | V26: 240 | W26: =133+12 -> 145 | X26: =+AC26/U26 -> 12 | Y26: =+W26+X26 -> 157 | Z26: =+V26-Y26 -> 83 | AA26: 4.3319547e+10 | AB26: 2.8381772e+10 | AC26: =SUM(AD26:AO26) -> 3.585066e+09 | AD26: 2.987555e+08 | AE26: 2.987555e+08 | AF26: 2.987555e+08 | AG26: 2.987555e+08 | AH26: 2.987555e+08 | AI26: 2.987555e+08 | AJ26: 2.987555e+08 | AK26: 2.987555e+08 | AL26: 2.987555e+08 | AM26: 2.987555e+08 | AN26: 2.987555e+08 | AO26: 2.987555e+08 | AP26: =+AA26+AC26 -> 4.6904613e+10 | AQ26: =IF(AS26=$AS$24,((T26-AP26)*0),T26-AP26) -> 2.4796706e+10 | AV26: Ok | AW26: =IFERROR(VLOOKUP(G26,'[70]Detail Deprec_202508'!$D$33:$I$357,6,FALSE),0) -> 2.987555e+08 | AX26: =AW26-AK26 -> 0.00058341026
A27: 2 | B27: CLC | C27: CLCWH | D27: 152 | E27: WH2 | F27: CLC131-004 | G27: BLD000063 | H27: 42398 | I27: Building | J27: 84 | K27: IMB Tax Warehouse Phase II | L27: Kawasan Industri Terpadu Indonesia China (KITIC) Kav. 20, Cikarang, West Java | M27: Cikarang Logistic Center | N27: 2016 | R27: 1 | T27: 2061766435 | U27: =+T27/V27 -> 8590693.5 | V27: 240 | W27: =108+12 -> 120 | X27: =+AC27/U27 -> 12 | Y27: =+W27+X27 -> 132 | Z27: =+V27-Y27 -> 108 | AA27: 1.0308832e+09 | AB27: 1.0308832e+09 | AC27: =SUM(AD27:AO27) -> 1.0308832e+08 | AD27: 8590693.5 | AE27: 8590693.5 | AF27: 8590693.5 | AG27: 8590693.5 | AH27: 8590693.5 | AI27: 8590693.5 | AJ27: 8590693.5 | AK27: 8590693.5 | AL27: 8590693.5 | AM27: 8590693.5 | AN27: 8590693.5 | AO27: 8590693.5 | AP27: =+AA27+AC27 -> 1.1339715e+09 | AQ27: =IF(AS27=$AS$24,((T27-AP27)*0),T27-AP27) -> 9.277949e+08 | AV27: Ok | AW27: =IFERROR(VLOOKUP(G27,'[70]Detail Deprec_202508'!$D$33:$I$357,6,FALSE),0) -> 8590693.5 | AX27: =AW27-AK27 -> 0.0008333344
A28: 3 | B28: CLC | C28: CLCWH | D28: 152 | E28: WH2 | F28: CLC131-002 | G28: BLD000064 | H28: 42387 | I28: Building | J28: 05 | K28: Lobby & Office Phase 2 | L28: Kawasan Industri Terpadu Indonesia China (KITIC) Kav. 20, Cikarang, West Java | M28: Cikarang Logistic Center | N28: 2016 | R28: 1 | T28: 5000000000 | U28: =+T28/V28 -> 20833333 | V28: 240 | W28: =108+12 -> 120 | X28: =+AC28/U28 -> 12 | Y28: =+W28+X28 -> 132 | Z28: =+V28-Y28 -> 108 | AA28: 2.5e+09 | AB28: 2.5e+09 | AC28: =SUM(AD28:AO28) -> 2.5e+08 | AD28: 20833333 | AE28: 20833333 | AF28: 20833333 | AG28: 20833333 | AH28: 20833333 | AI28: 20833333 | AJ28: 20833333 | AK28: 20833333 | AL28: 20833333 | AM28: 20833333 | AN28: 20833333 | AO28: 20833333 | AP28: =+AA28+AC28 -> 2.75e+09 | AQ28: =IF(AS28=$AS$24,((T28-AP28)*0),T28-AP28) -> 2.25e+09 | AV28: Ok | AW28: =IFERROR(VLOOKUP(G28,'[70]Detail Deprec_202508'!$D$33:$I$357,6,FALSE),0) -> 20833333 | AX28: =AW28-AK28 -> -0.0033333339
A29: 4 | B29: CLC | C29: CLCWH | D29: 152 | E29: WH2 | F29: CLC131-002 | G29: BLD000065 | H29: 42387 | I29: Building | J29: 05 | K29: Warehouse Phase 2 Floor 2 | L29: Kawasan Industri Terpadu Indonesia China (KITIC) Kav. 20, Cikarang, West Java | M29: Cikarang Logistic Center | N29: 2016 | R29: 1 | T29: 44455000000 | U29: =+T29/V29 -> 1.8522917e+08 | V29: 240 | W29: =108+12 -> 120 | X29: =+AC29/U29 -> 12 | Y29: =+W29+X29 -> 132 | Z29: =+V29-Y29 -> 108 | AA29: 2.22275e+10 | AB29: 2.22275e+10 | AC29: =SUM(AD29:AO29) -> 2.22275e+09 | AD29: 1.8522917e+08 | AE29: 1.8522917e+08 | AF29: 1.8522917e+08 | AG29: 1.8522917e+08 | AH29: 1.8522917e+08 | AI29: 1.8522917e+08 | AJ29: 1.8522917e+08 | AK29: 1.8522917e+08 | AL29: 1.8522917e+08 | AM29: 1.8522917e+08 | AN29: 1.8522917e+08 | AO29: 1.8522917e+08 | AP29: =+AA29+AC29 -> 2.445025e+10 | AQ29: =IF(AS29=$AS$24,((T29-AP29)*0),T29-AP29) -> 2.000475e+10 | AV29: Ok | AW29: =IFERROR(VLOOKUP(G29,'[70]Detail Deprec_202508'!$D$33:$I$357,6,FALSE),0) -> 1.8522917e+08 | AX29: =AW29-AK29 -> 0.0033333302
A30: 5 | B30: CLC | C30: CLCWH | D30: 152 | E30: WH2 | F30: CLC131-002 | G30: BLD000066 | H30: 42387 | I30: Building | J30: 05 | K30: Warehouse Phase 2 Floor 1 | L30: Kawasan Industri Terpadu Indonesia China (KITIC) Kav. 20, Cikarang, West Java | M30: Cikarang Logistic Center | N30: 2016 | R30: 1 | T30: 49455000000 | U30: =+T30/V30 -> 206062500 | V30: 240 | W30: =108+12 -> 120 | X30: =+AC30/U30 -> 12 | Y30: =+W30+X30 -> 132 | Z30: =+V30-Y30 -> 108 | AA30: 24727500000 | AB30: 24727500000 | AC30: =SUM(AD30:AO30) -> 2472750000 | AD30: 206062500 | AE30: 206062500 | AF30: 206062500 | AG30: 206062500 | AH30: 206062500 | AI30: 206062500 | AJ30: 206062500 | AK30: 206062500 | AL30: 206062500 | AM30: 206062500 | AN30: 206062500 | AO30: 206062500 | AP30: =+AA30+AC30 -> 27200250000 | AQ30: =IF(AS30=$AS$24,((T30-AP30)*0),T30-AP30) -> 22254750000 | AV30: Ok | AW30: =IFERROR(VLOOKUP(G30,'[70]Detail Deprec_202508'!$D$33:$I$357,6,FALSE),0) -> 206062500 | AX30: =AW30-AK30 -> 0
