Workbook
Name \0: #N/A
Name \a: #REF!
Name \c: #REF!
Name \p: #REF!
Name \q: [1]FRYPROD!#REF!
Name ___RSE2: '[2]CMA Calculations'!$H$1066
Name __DAT1: "$#REF!.$A$1:$A$394"
Name __DAT10: #REF!
Name __DAT11: #REF!
Name __DAT12: #REF!
Name __DAT13: #REF!
Name __DAT14: #REF!
Name __DAT15: #REF!
Name __DAT16: #REF!
Name __DAT2: "$#REF!.$B$1:$B$394"
Name __DAT3: "$#REF!.$#REF!$#REF!:$#REF!$#REF!"
Name __DAT6: #REF!
Name __DAT7: #REF!
Name __DAT8: #REF!
Name __DAT9: #REF!
Name __NPW1: '[3]Permanent info'!$E$5
Name __NPW10: '[3]Permanent info'!$R$5
Name __NPW11: '[3]Permanent info'!$S$5
Name __NPW2: '[3]Permanent info'!$G$5
Name __NPW3: '[3]Permanent info'!$H$5
Name __NPW4: '[3]Permanent info'!$I$5
Name __NPW5: '[3]Permanent info'!$K$5
Name __NPW6: '[3]Permanent info'!$L$5
Name __NPW7: '[3]Permanent info'!$M$5
Name __NPW8: '[3]Permanent info'!$O$5
Name __NPW9: '[3]Permanent info'!$Q$5
Name __poc01: #REF!
Name __poc02: #REF!
Name __poc03: #REF!
Name __poc04: #REF!
Name __poc05: #REF!
Name __PPH25: #REF!
Name __RSE2: '[2]CMA Calculations'!$H$1066
Name __vib01: #REF!
Name __vib02: #REF!
Name __vib03: #REF!
Name __vib04: #REF!
Name __vib05: #REF!
Name __vib06: #REF!
Name __vib07: #REF!
Name __WS1: #REF!
Name __WS2: #REF!
Name _1: #REF!
Name _15: #REF!
Name _15_2: #REF!
Name _3: #REF!
Name _CDD763: #REF!
Name _DAT1: "$#REF!.$A$1:$A$394"
Name _DAT10: #REF!
Name _DAT11: #REF!
Name _DAT12: #REF!
Name _DAT13: #REF!
Name _DAT14: #REF!
Name _DAT15: #REF!
Name _DAT16: #REF!

Sheet TB
B1: TB July 2020
B3: Ledger account | C3: Name | D3: Opening balance | E3: Debit | F3: Credit | G3: Closing balance | I3: MainAccount | J3: Name | K3: Opening balance | L3: Debit | M3: Credit | N3: Closing balance
B4: 1510000 | C4: Land | G4: =IFERROR(VLOOKUP(B4,$I$4:$N$29,6,FALSE),0) -> 102037368651 | H4: =LEFT(I4,3) -> 151 | I4: 1510000 | J4: Land | K4: 102037368651 | L4: 0 | M4: 0 | N4: 102037368651 | P4: 102037368651 | Q4: =P4-N4 -> 0
B5: 1520000 | C5: Buildings | G5: =IFERROR(VLOOKUP(B5,$I$4:$N$29,6,FALSE),0) -> 2.8312631e+11 | H5: =LEFT(I5,3) -> 152 | I5: 1520000 | J5: Buildings | K5: 2.8312631e+11 | L5: 0 | M5: 0 | N5: 2.8312631e+11 | P5: 2.8331437e+11 | Q5: =P5-N5 -> 188052750
B6: 1530000 | C6: Structures | G6: =IFERROR(VLOOKUP(B6,$I$4:$N$29,6,FALSE),0) -> 9.7607306e+09 | H6: =LEFT(I6,3) -> 153 | I6: 1530000 | J6: Structures | K6: 9.7607306e+09 | L6: 0 | M6: 0 | N6: 9.7607306e+09 | P6: 9.4307277e+09 | Q6: =P6-N6 -> -330002944
B7: 1540000 | C7: Machinery & Equipment | G7: =IFERROR(VLOOKUP(B7,$I$4:$N$29,6,FALSE),0) -> 7.7916025e+10 | H7: =LEFT(I7,3) -> 154 | I7: 1540000 | J7: Machinery & Equipment | K7: 7.7916025e+10 | L7: 0 | M7: 0 | N7: 7.7916025e+10 | P7: 7.8722001e+10 | Q7: =P7-N7 -> 8.0597534e+08
B8: 1550000 | C8: Vehicles | G8: =IFERROR(VLOOKUP(B8,$I$4:$N$29,6,FALSE),0) -> 4.257898e+11 | H8: =LEFT(I8,3) -> 155 | I8: 1550000 | J8: Vehicles | K8: 4.2930926e+11 | L8: 1154788214 | M8: 4674244400 | N8: 4.257898e+11 | P8: 4.4178311e+11 | Q8: =P8-N8 -> 1.5993311e+10
B9: 1560000 | C9: Tools, Furniture & Fixtures | G9: =IFERROR(VLOOKUP(B9,$I$4:$N$29,6,FALSE),0) -> 1.4359284e+10 | H9: =LEFT(I9,3) -> 156 | I9: 1560000 | J9: Tools, Furniture & Fixtures | K9: 1.4359284e+10 | L9: 0 | M9: 0 | N9: 1.4359284e+10 | P9: 1.3614925e+10 | Q9: =P9-N9 -> -7.4435809e+08
B10: 1585400 | C10: Lease Hold Improvement Machine& Equipment | G10: =IFERROR(VLOOKUP(B10,$I$4:$N$29,6,FALSE),0) -> 0 | H10: =LEFT(I10,3) -> 161 | I10: 1615500 | J10: Down Payment: Vehicles | K10: 533400001 | L10: 0 | M10: 339600000 | N10: 193800001 | P10: 620000000 | Q10: =P10-N10 -> 426199999
B11: 1585500 | C11: Lease Hold Improvement Vehicle | G11: =IFERROR(VLOOKUP(B11,$I$4:$N$29,6,FALSE),0) -> 0 | H11: =LEFT(I11,3) -> 172 | I11: 1720000 | J11: System & Software | K11: 588800000 | L11: 0 | M11: 0 | N11: 588800000 | P11: 1434345000 | Q11: =P11-N11 -> 845545000
B12: 1615200 | C12: Down Payment: Building | G12: =IFERROR(VLOOKUP(B12,$I$4:$N$29,6,FALSE),0) -> 0 | H12: =LEFT(I12,3) -> 251 | I12: 2515200 | J12: Accumulated Depreciation: Building | K12: -1.674119e+11 | L12: 0 | M12: 1.1347742e+09 | N12: -1.6854668e+11 | P12: 0 | Q12: =P12-N12 -> 1.6854668e+11
B13: 1615300 | C13: Down Payment: Structures | G13: =IFERROR(VLOOKUP(B13,$I$4:$N$29,6,FALSE),0) -> 0 | H13: =LEFT(I13,3) -> 251 | I13: 2515300 | J13: Accumulated Depreciation: Structures | K13: -9.0335391e+09 | L13: 0 | M13: 25060967 | N13: -9.0586e+09 | P13: -1.1295559e+11 | Q13: =P13-N13 -> -1.0389699e+11
B14: 1615400 | C14: Down Payment: Machinary & Equipment | G14: =IFERROR(VLOOKUP(B14,$I$4:$N$29,6,FALSE),0) -> 0 | H14: =LEFT(I14,3) -> 251 | I14: 2515400 | J14: Accumulated Depreciation: Machine | K14: -6.9740764e+10 | L14: 0 | M14: 1.4068039e+08 | N14: -6.9881444e+10 | P14: -7.9542433e+09 | Q14: =P14-N14 -> 6.1927201e+10
B15: 1615500 | C15: Down Payment: Vehicles | G15: =IFERROR(VLOOKUP(B15,$I$4:$N$29,6,FALSE),0) -> 193800001 | H15: =LEFT(I15,3) -> 251 | I15: 2515500 | J15: Accumulated Depreciation: Vehicles | K15: -3.2151482e+11 | L15: 4674244400 | M15: 2.2399987e+09 | N15: -3.1908058e+11 | P15: -6.5588325e+10 | Q15: =P15-N15 -> 2.5349225e+11
... B18: 2515400 | C18: Accumulated Depreciation: Machine | G18: =IFERROR(VLOOKUP(B18,$I$4:$N$29,6,FALSE),0) -> -6.9881444e+10 | H18: =LEFT(I18,3) -> 421 | I18: 4215500 | J18: Gain from Sold FA Vehicles | K18: -3199549552 | L18: 0 | M18: 569621622 | N18: -3769171174 | P18: -1.1221614e+09 | Q18: =P18-N18 -> 2.6470097e+09
B19: 2515500 | C19: Accumulated Depreciation: Vehicles | G19: =IFERROR(VLOOKUP(B19,$I$4:$N$29,6,FALSE),0) -> -3.1908058e+11 | H19: =LEFT(I19,3)
B20: 2515600 | C20: Accumulated Depreciation: Tools, Furniture & Fixtures | G20: =IFERROR(VLOOKUP(B20,$I$4:$N$29,6,FALSE),0) -> -1.1956838e+10 | H20: =LEFT(I20,3)
B21: 1615600 | C21: Down Payment: Tools, Furniture & Fixtures | G21: =IFERROR(VLOOKUP(B21,$I$4:$N$29,6,FALSE),0) -> 0 | H21: =LEFT(I21,3)
B22: 4215500 | C22: Gain from Sold FA Vehicles | G22: =IFERROR(VLOOKUP(B22,$I$4:$N$29,6,FALSE),0) -> -3769171174
B23: 4215600 | C23: Gain from Sold FA Tools, Furniture & Fixtures | G23: =IFERROR(VLOOKUP(B23,$I$4:$N$29,6,FALSE),0) -> 0
B24: 4215400 | C24: Gain from Sold FA Machinary & Equipment | G24: =IFERROR(VLOOKUP(B24,$I$4:$N$29,6,FALSE),0) -> 0
B25: 4215200 | C25: Gain from Sold FA Building | G25: =IFERROR(VLOOKUP(B25,$I$4:$N$29,6,FALSE),0) -> 0
B26: 1720000 | C26: System & Software | G26: =IFERROR(VLOOKUP(B26,$I$4:$N$29,6,FALSE),0) -> 588800000
B27: 2540000 | C27: Accumulated Depreciation: System & Software | G27: =IFERROR(VLOOKUP(B27,$I$4:$N$29,6,FALSE),0) -> -1.1310567e+08
B28: 5215500 | G28: =IFERROR(VLOOKUP(B28,$I$4:$N$29,6,FALSE),0) -> 0
B29: 5215600 | G29: =IFERROR(VLOOKUP(B29,$I$4:$N$29,6,FALSE),0) -> 0
D32: =H4&"*,"&H5&"*,"&H6&"*,"&H7&"*,"&H8&"*,"&H9&"*,"&H10&"*,"&H11&"*,"&H13&"*,"&H14&"*,"&H15&"*,"&H16&"*,"&H17&"*,"&H18&"*,"&H19&"*,"&H20&"*,"&H12 -> 151*,152*,153*,154*,155*,156*,161*,172*,251*,251*,251*,251*,254*,421*,*,*,251
D33: 151*,152*,153*,154*,155*,156*,161*,251*,161*158*,42*,17*,254*,52*
J39: MNE000001
J40: MNE000002
J41: MNE000003
J42: MNE000004
J43: MNE000005
J44: MNE000006
J45: MNE000007
J46: MNE000008
J47: FNF000002
J48: FNF000003
J49: FNF000004
J50: FNF000005
...

Sheet TOTAL
A1: PT. Sankyu Indonesia International
A2: Total of Fixed Asset
A3: 30 Jun 2026
A5: No. | B5: Name of Fixed Assets | C5: Fixed Asset (List) | I5: D365
C6: Beginning Balance | D6: Additional | E6: Disposals | F6: Adjustment | G6: Ending Balace | I6: Total | J6: Different
G7: a | I7: b | J7: c = a - b
A8: Purchase Price | M8: TB | N8: List | O8: Diff TB | P8: Diff List
A9: 152 | B9: Buildings | C9: 2.8312631e+11 | D9: =SUMIFS(FA_2026!$S$10:$S$80,FA_2026!$D$10:$D$80,TOTAL!$A$9,FA_2026!$AQ$10:$AQ$80,TOTAL!$D$6) -> 0 | E9: =-SUMIFS(FA_2026!$S$10:$S$78,FA_2026!$D$10:$D$78,TOTAL!$A$9,FA_2026!$AR$10:$AR$78,TOTAL!$E$6) -> 0 | G9: =+C9+D9+E9+F9 -> 2.8312631e+11 | I9: =TB!G5 -> 2.8312631e+11 | J9: =+G9-I9 -> 0 | M9: 2.8312631e+11 | N9: =FA_2026!S81 -> 2.8312631e+11 | O9: =M9-C9 -> 0 | P9: =(C9+D9)-N9 -> 0
A10: 153 | B10: Structures | C10: 9.8908306e+09 | D10: =SUMIFS(FA_2026!$S$82:$S$147,FA_2026!$D$82:$D$147,TOTAL!$A$10,FA_2026!$AQ$82:$AQ$147,TOTAL!$D$6) -> 59325000 | E10: =-SUMIFS(FA_2026!$S$82:$S$147,FA_2026!$D$82:$D$147,TOTAL!$A$10,FA_2026!$AR$82:$AR$147,TOTAL!$E$6) -> -189425000 | G10: =+C10+D10+E10+F10 -> 9.7607306e+09 | I10: =TB!G6 -> 9.7607306e+09 | J10: =+G10-I10 -> 0 | M10: 9.8908306e+09 | N10: =FA_2026!S148 -> 9.9501556e+09 | O10: =M10-C10 -> 0 | P10: =(C10+D10)-N10 -> 0
A11: 154 | B11: Machinery & Equipments | C11: 7.7752435e+10 | D11: =SUMIFS(FA_2026!$S$149:$S$521,FA_2026!$D$149:$D$521,TOTAL!$A$11,FA_2026!$AQ$149:$AQ$521,TOTAL!$D$6) -> 180890000 | E11: =-SUMIFS(FA_2026!$S$149:$S$521,FA_2026!$D$149:$D$521,TOTAL!$A$11,FA_2026!$AR$149:$AR$521,TOTAL!$E$6) -> -17300000 | G11: =+C11+D11+E11+F11 -> 7.7916025e+10 | I11: =TB!G7 -> 7.7916025e+10 | J11: =+G11-I11 -> 0 | M11: 7.7752435e+10 | N11: =FA_2026!S522 -> 7.7933325e+10 | O11: =M11-C11 -> 0 | P11: =(C11+D11)-N11 -> 0
A12: 159 | B12: Vessels | C12: 0 | D12: 0 | E12: 0 | G12: =+C12+D12+E12+F12 -> 0 | I12: 0 | J12: =+G12-I12 -> 0 | O12: =M12-C12 -> 0 | P12: =(C12+D12)-N12 -> 0
A13: 155 | B13: Vehicles | C13: 4.3479287e+11 | D13: =SUMIFS(FA_2026!$S$523:$S$936,FA_2026!$D$523:$D$936,TOTAL!$A$13,FA_2026!$AQ$523:$AQ$936,TOTAL!$D$6) -> 14181941541 | E13: =-SUMIFS(FA_2026!$S$523:$S$936,FA_2026!$D$523:$D$936,TOTAL!$A$13,FA_2026!$AR$523:$AR$936,TOTAL!$E$6) -> -2.318501e+10 | G13: =C13+D13+E13+F13 -> 4.257898e+11 | I13: =TB!G8 -> 4.257898e+11 | J13: =+G13-I13 -> 1.000061 | M13: 4.3479287e+11 | N13: =FA_2026!S937 -> 4.4897481e+11 | O13: =M13-C13 -> -1.000061 | P13: =(C13+D13)-N13 -> 0
A14: 156 | B14: Tools, Furnitures & Fixtures | C14: 1.4282999e+10 | D14: =SUMIFS(FA_2026!$S$938:$S$1143,FA_2026!$D$938:$D$1143,TOTAL!$A$14,FA_2026!$AQ$938:$AQ$1143,TOTAL!$D$6) -> 107379000 | E14: =-SUMIFS(FA_2026!$S$938:$S$1143,FA_2026!$D$938:$D$1143,TOTAL!$A$14,FA_2026!$AR$938:$AR$1143,TOTAL!$E$6) -> -31094062 | G14: =+C14+D14+E14+F14 -> 1.4359284e+10 | I14: =TB!G9 -> 1.4359284e+10 | J14: =+G14-I14 -> -0.059997559 | M14: 1.4282999e+10 | N14: =FA_2026!S1144 -> 1.4390378e+10 | O14: =M14-C14 -> 0.059997559 | P14: =(C14+D14)-N14 -> -0.059997559
A15: 172 | B15: System | C15: 588800000 | D15: =SUMIFS(FA_2026!$S$938:$S$1152,FA_2026!$D$938:$D$1152,TOTAL!$A$15,FA_2026!$AQ$938:$AQ$1152,TOTAL!$D$6) -> 0 | E15: =-SUMIFS(FA_2026!$S$938:$S$1152,FA_2026!$D$938:$D$1152,TOTAL!$A$15,FA_2026!$AR$938:$AR$1152,TOTAL!$E$6) -> 0 | G15: =+C15+D15+E15+F15 -> 588800000 | I15: =TB!G26 -> 588800000 | J15: =+G15-I15 -> 0 | M15: 588800000 | N15: =FA_2026!S1152 -> 588800000 | O15: =M15-C15 -> 0 | P15: =(C15+D15)-N15 -> 0
A16: 151 | B16: Land | C16: 102037368651 | D16: =-SUMIFS(FA_2026!$S$1153:$S$1246,FA_2026!$D$1153:$D$1246,TOTAL!$A$16,FA_2026!$AQ$1153:$AQ$1246,TOTAL!$D$6) -> 0 | E16: =-SUMIFS(FA_2026!$S$1153:$S$1159,FA_2026!$D$1153:$D$1159,TOTAL!$A$16,FA_2026!$AR$1153:$AR$1159,TOTAL!$E$6) -> 0 | G16: =+C16+D16+E16+F16 -> 102037368651 | I16: 102037368651 | J16: =+G16-I16 -> 0 | M16: 102037368651 | N16: =FA_2026!S1161 -> 102037368651 | O16: =M16-C16 -> 0 | P16: =(C16+D16)-N16 -> 0
A17: 161 | B17: Construction In Process | C17: 2668541541 | D17: =SUMIFS(FA_2026!$S$1162:$S$1172,FA_2026!$D$1162:$D$1172,TOTAL!$A$17,FA_2026!$AQ$1162:$AQ$1172,TOTAL!$D$6) -> 1079550000 | E17: =-SUMIFS(FA_2026!$AA$1162:$AA$1172,FA_2026!$D$1162:$D$1172,TOTAL!$A$17,FA_2026!$AR$1162:$AR$1172,TOTAL!$E$6) -> -3554291541 | G17: =+C17+D17+E17+F17 -> 193800000 | I17: =SUM(TB!G12:G15,TB!G21) -> 193800001 | J17: =+G17-I17 -> -1 | M17: 2668541542 | N17: =FA_2026!S1172 -> 3748091541 | O17: =M17-C17 -> 1 | P17: =(C17+D17)-N17 -> 0
B18: Grand Total | C18: 9.2501902e+11 | D18: =SUM(D9:D17) -> 15609085541 | E18: =SUM(E9:E17) -> -2.697712e+10 | F18: =SUM(F9:F17) -> 0 | G18: =SUM(G9:G17) -> 9.1377212e+11 | I18: =SUM(I9:I17) -> 9.1377212e+11 | J18: =SUM(J9:J17) -> -0.059936523
C19: 9.134756e+11 | G19: =G18-G17 -> 9.1357832e+11
A20: Accumulated Depreciation (251)
A21: 152 | B21: Buildings | C21: 1.6173803e+11 | D21: =SUM(FA_2026!AB81) -> 6.8086453e+09 | E21: =-SUMIFS(FA_2026!$AO$10:$AO$1952,FA_2026!$D$10:$D$1952,TOTAL!$A21,FA_2026!$AR$10:$AR$1952,TOTAL!$E$6) -> 0 | G21: =SUM(C21:E21) -> 1.6854668e+11 | I21: =TB!G16 -> -1.6854668e+11 | J21: =+G21+I21 -> -0.31115723
A22: 153 | B22: Structures | C22: 9.0976592e+09 | D22: =SUM(FA_2026!AB148) -> 1.503658e+08 | E22: =-SUMIFS(FA_2026!$AO$10:$AO$1952,FA_2026!$D$10:$D$1952,TOTAL!$A22,FA_2026!$AR$10:$AR$1952,TOTAL!$E$6) -> -189425000 | G22: =SUM(C22:E22) -> 9.0586e+09 | I22: =TB!G17 -> -9.0586e+09 | J22: =+G22+I22 -> 0.92000198
A23: 154 | B23: Machinery & Equipments | C23: 6.9012211e+10 | D23: =SUM(FA_2026!AB522) -> 8.8653249e+08 | E23: =-SUMIFS(FA_2026!$AO$10:$AO$1952,FA_2026!$D$10:$D$1952,TOTAL!$A23,FA_2026!$AR$10:$AR$1952,TOTAL!$E$6) -> -17300000 | G23: =SUM(C23:E23) -> 6.9881444e+10 | I23: =TB!G18 -> -6.9881444e+10 | J23: =+G23+I23 -> -5.6826935
A24: 159 | B24: Vessels | C24: 0 | D24: 0 | E24: =-SUMIFS(FA_2026!$AO$10:$AO$1952,FA_2026!$D$10:$D$1952,TOTAL!$A24,FA_2026!$AR$10:$AR$1952,TOTAL!$E$6) -> 0 | G24: =SUM(C24:E24) -> 0 | J24: =+G24+I24 -> 0
A25: 155 | B25: Vehicles | C25: 3.2864007e+11 | D25: =SUM(FA_2026!AB937) -> 1.3625518e+10 | E25: =-SUMIFS(FA_2026!$AO$10:$AO$1952,FA_2026!$D$10:$D$1952,TOTAL!$A25,FA_2026!$AR$10:$AR$1952,TOTAL!$E$6) -> -2.318501e+10 | G25: =SUM(C25:E25) -> 3.1908058e+11 | I25: =TB!G19 -> -3.1908058e+11 | J25: =+G25+I25 -> -1.4338989
A26: 156 | B26: Tools, Furnitures & Fixtures | C26: 1.1435715e+10 | D26: =SUM(FA_2026!AB1144) -> 5.5221737e+08 | E26: =-SUMIFS(FA_2026!$AO$10:$AO$1952,FA_2026!$D$10:$D$1952,TOTAL!$A26,FA_2026!$AR$10:$AR$1952,TOTAL!$E$6) -> -31094062 | G26: =SUM(C26:E26) -> 1.1956838e+10 | I26: =TB!G20 -> -1.1956838e+10 | J26: =+G26+I26 -> 6.4783344
A27: 172 | B27: System | C27: 53475667 | D27: =SUM(FA_2026!AB1152) -> 59630000 | E27: =-SUMIFS(FA_2026!$AO$10:$AO$1952,FA_2026!$D$10:$D$1952,TOTAL!$A27,FA_2026!$AR$10:$AR$1952,TOTAL!$E$6) -> 0 | G27: =SUM(C27:E27) -> 1.1310567e+08 | I27: =TB!G27 -> -1.1310567e+08 | J27: =+G27+I27 -> 0.46666665
B28: Grand Total | C28: 5.7996202e+11 | D28: =SUM(D21:D27) -> 2.2082909e+10 | E28: =SUM(E21:E27) -> -2.3422829e+10 | F28: =SUM(F21:F27) -> 0 | G28: =SUM(G21:G27) -> 5.7863724e+11 | I28: =SUM(I21:I27) -> -5.7863724e+11 | J28: =SUM(J21:J26) -> -0.029413223
C30: =C18-C28 -> 3.45057e+11 | E30: Fixed Asset (Net) | G30: =+G18-G28 -> 3.3513488e+11
A31: Net Book Value (251) | C31: =C30+C40 -> 6.7999808e+11
A32: 151 | B32: Land | C32: =G16 -> 102037368651
A33: 152 | B33: Buildings | C33: =G9-G21 -> 1.1457964e+11 | D33: =FA_2026!AP81 -> 1.1457964e+11 | E33: =D33-C33 -> -0.33139038
A34: 153 | B34: Structures | C34: =G10-G22 -> 7.0213059e+08 | D34: =FA_2026!AP148 -> 7.0213059e+08 | E34: =D34-C34 -> -5.3666638
A35: 154 | B35: Machinery & Equipments | C35: =G11-G23 -> 8.0345815e+09 | D35: =FA_2026!AP522 -> 8.0345815e+09 | E35: =D35-C35 -> -11.967809
A36: 159 | B36: Vessels | C36: =G12-G24 -> 0 | E36: =D36-C36 -> 0
A37: 155 | B37: Vehicles | C37: =G13-G25 -> 1.0670922e+11 | D37: =FA_2026!AP937 -> 1.0670922e+11 | E37: =D37-C37 -> -30.003891
A38: 156 | B38: Tools, Furnitures & Fixtures | C38: =G14-G26 -> 2.4024452e+09 | D38: =FA_2026!AP1144 -> 2.4024452e+09 | E38: =D38-C38 -> -8.2083335
A39: 172 | B39: System | C39: =G15-G27 -> 4.7569433e+08 | D39: =FA_2026!AP1152 -> 4.7569433e+08 | E39: =D39-C39 -> 0
C40: =SUM(C32:C39) -> 3.3494108e+11 | D40: =FA_2026!AP1173+FA_2026!AA1161 -> 3.3494108e+11 | E40: =D40-C40 -> -55.877991 | G40: Land

Sheet FA_2026
A1: PT. SANKYU INDONESIA INTERNATIONAL
A2: LIST OF FIXED ASSETS AND DEPRECIATION SCHEDULE
A3: =TOTAL!A3 -> 30 Jun 2026
S4: =#REF!/#REF! -> #REF!
A7: No. | B7: Site/ Location | C7: Job | D7: Account | E7: Asset | F7: Fixed asset number | G7: Purchase Date | H7: Group | I7: Voucher | J7: Name of Fixed Asset | K7: Maker/Type/Location | L7: Capacity/Size/User | M7: Year | N7: Police | O7: Machine | P7: Chasis | Q7: Quantity | R7: Valas | S7: Purchase Price | T7: Monthly Depreciation | U7: Depreciation Period | Z7: Accumulated Depreciation | AA7: Net Book Value | AB7: Depreciation Expense Current | AC7: DEPRECIATION 2025 ( MONTHLY ) | AO7: Accumulated Depreciation | AP7: Net Book Value | AQ7: Status | AS7: Acquisition | AT7: Remark | AU7: Photo Status | AW7: Checker Name ( A ) | AY7: Existing ( B ) | BA7: If Yes (Existing) ( C ) | BC7: If Not Used ( D ) | BE7: Sticker ( E ) | BL7: Asset
D8: No. | E8: No. | F8: AX | I8: No. | N8: No. | O8: No. | P8: No. | U8: Total | V8: Acc. 2025 | W8: Yearly 2026 | X8: Until 2026 | Y8: Remain > 2026 | Z8: 31 December 2025 | AA8: 31 December 2025 | AB8: =+A3 -> 30 Jun 2026 | AC8: Jan | AD8: Feb | AE8: Mar | AF8: Apr | AG8: May | AH8: Jun | AI8: Jul | AJ8: Aug | AK8: Sep | AL8: Oct | AM8: Nov | AN8: Dec | AO8: =A3 -> 30 Jun 2026 | AP8: =+AO8 -> 30 Jun 2026 | AQ8: Additional | AR8: Disposals | AS8: Condition | AW8: Site | AX8: HO | AY8: Yes | AZ8: No | BA8: Still Used | BB8: Not Used | BC8: Repair | BD8: Disposals | BE8: Good | BF8: Bad | BL8: No.
S9: a | T9: b=a:c | U9: c | V9: d=h:b | W9: e=j:b | X9: f=d+e | Y9: g=c-f | Z9: l=h+j | AA9: m=a-l | AB9: j=total k (jAC-des) | AC9: k | AD9: k | AE9: k | AF9: k | AG9: k | AH9: k | AI9: k | AJ9: k | AK9: k | AL9: k | AM9: k | AN9: k | AO9: l=h+j | AP9: m=a-l | AV9: Check
A10: 1 | B10: HCT | C10: D30 | D10: 152 | E10: 3B-E-002 | F10: BLD000006 | G10: 35430 | H10: Building | I10: - | J10: Additional warehouse at Cilegon branch | K10: Jl. Raya Anyer Km. 121, Gunung Sugih, Ciwandan, Banten | Q10: 1 | S10: 41500000 | T10: =+S10/U10 -> 172916.67 | U10: 240 | V10: 0 | W10: =+AB10/T10 -> 0 | X10: =+V10+W10 -> 0 | Y10: =+U10-X10 -> 240 | Z10: 41500000 | AA10: 0 | AB10: =SUM(AC10:AH10) -> 0 | AO10: =+Z10+AB10 -> 41500000 | AP10: =IF(AR10=$AR$8,((S10-AO10)*0),S10-AO10) -> 0 | AU10: Ok | AV10: =VLOOKUP(F10,[78]!D365FinOps_API_Table[[FixedAssetNumber]:[Department]],80,FALSE) -> #REF! | BL10: 3B-E-002
A11: =+A10+1 -> 2 | B11: HCT | C11: D30 | D11: 152 | E11: 3B-E-001 | F11: BLD000007 | G11: 35430 | H11: Building | I11: - | J11: Warehouse at Cilegon branch | K11: Jl. Raya Anyer Km. 121, Gunung Sugih, Ciwandan, Banten | Q11: 1 | S11: 1890319104 | T11: =+S11/U11 -> 7876329.6 | U11: 240 | V11: 240 | W11: =+AB11/T11 -> 0 | X11: =+V11+W11 -> 240 | Y11: =+U11-X11 -> 0 | Z11: 1890319104 | AA11: 0 | AB11: =SUM(AC11:AH11) -> 0 | AO11: =+Z11+AB11 -> 1890319104 | AP11: =IF(AR11=$AR$8,((S11-AO11)*0),S11-AO11) -> 0 | AU11: Ok | AV11: =VLOOKUP(F11,[78]!D365FinOps_API_Table[[FixedAssetNumber]:[Department]],80,FALSE) -> #REF! | BL11: 3B-E-001
A12: =+A11+1 -> 3 | B12: JKTC | C12: D10 | D12: 152 | E12: - | F12: BLD000009 | G12: 36145 | H12: Building | I12: 10 | J12: Building for Construction at Kawasan Jababeka | K12: Kawasan Industri Jababeka, Jl Industri Selatan 2 Blok JJ no. 5, Cikarang West Java | Q12: 1 | S12: 373983750 | T12: =+S12/U12 -> 1558265.6 | U12: 240 | V12: 240 | W12: =+AB12/T12 -> 0 | X12: =+V12+W12 -> 240 | Y12: =+U12-X12 -> 0 | Z12: 373983750 | AA12: 0 | AB12: =SUM(AC12:AH12) -> 0 | AO12: =+Z12+AB12 -> 373983750 | AP12: =IF(AR12=$AR$8,((S12-AO12)*0),S12-AO12) -> 0 | AU12: Ok | AV12: =VLOOKUP(F12,[78]!D365FinOps_API_Table[[FixedAssetNumber]:[Department]],80,FALSE) -> #REF! | BL12: -
A13: =+A12+1 -> 4 | B13: JKTC | C13: D10 | D13: 152 | E13: - | F13: BLD000010 | G13: 36250 | H13: Building | I13: 4012 | J13: Renovation of building at Kawasan Jababeka | K13: Kawasan Industri Jababeka, Jl Industri Selatan 2 Blok JJ no. 5, Cikarang West Java | Q13: 1 | S13: 373993200 | T13: =+S13/U13 -> 1558305 | U13: 240 | V13: 240 | W13: =+AB13/T13 -> 0 | X13: =+V13+W13 -> 240 | Y13: =+U13-X13 -> 0 | Z13: 373993200 | AA13: 0 | AB13: =SUM(AC13:AH13) -> 0 | AO13: =+Z13+AB13 -> 373993200 | AP13: =IF(AR13=$AR$8,((S13-AO13)*0),S13-AO13) -> 0 | AU13: Ok | AV13: =VLOOKUP(F13,[78]!D365FinOps_API_Table[[FixedAssetNumber]:[Department]],80,FALSE) -> #REF! | BL13: -
A14: =+A13+1 -> 5 | B14: CLGC | C14: D30 | D14: 152 | E14: 7-E-005 | F14: BLD000015 | G14: 38579 | H14: Building | I14: 3066 | J14: Office at Bojonegoro (40 M2) | K14: Jl. Bojonegara Salira I, RT. 018/08, Margagiri, Bojonegara, Banten | Q14: 1 | S14: 52475000 | T14: =+S14/U14 -> 874583.33 | U14: 60 | V14: 60 | W14: =+AB14/T14 -> 0 | X14: =+V14+W14 -> 60 | Y14: =+U14-X14 -> 0 | Z14: 52475000 | AA14: 0 | AB14: =SUM(AC14:AH14) -> 0 | AO14: =+Z14+AB14 -> 52475000 | AP14: =IF(AR14=$AR$8,((S14-AO14)*0),S14-AO14) -> 0 | AU14: Ok | AV14: =VLOOKUP(F14,[78]!D365FinOps_API_Table[[FixedAssetNumber]:[Department]],80,FALSE) -> #REF! | BL14: 7-E-005
A15: =+A14+1 -> 6 | B15: HCT | C15: D30 | D15: 152 | E15: 3B-E-003 | F15: BLD000016 | G15: 38715 | H15: Building | I15: 17 | J15: Expansion Canopy for Warehouse | K15: Jl. Raya Anyer Km. 121, Gunung Sugih, Ciwandan, Banten | Q15: 1 | S15: 692000000 | T15: =+S15/U15 -> 2883333.3 | U15: 240 | V15: 240 | W15: =+AB15/T15 -> 0 | X15: =+V15+W15 -> 240 | Y15: =+U15-X15 -> 0 | Z15: 6.92e+08 | AA15: -2.3841858e-07 | AB15: =SUM(AC15:AH15) -> 0 | AO15: =+Z15+AB15 -> 6.92e+08 | AP15: =IF(AR15=$AR$8,((S15-AO15)*0),S15-AO15) -> -2.3841858e-07 | AU15: Ok | AV15: =VLOOKUP(F15,[78]!D365FinOps_API_Table[[FixedAssetNumber]:[Department]],80,FALSE) -> #REF! | BL15: 3B-E-003
A16: =+A15+1 -> 7 | B16: JOIN | C16: D30 | D16: 152 | E16: 3B-E-003 | F16: BLD000017 | G16: 38715 | H16: Building | I16: 17 | J16: Expansion Canopy for Warehouse | K16: Jl. Raya Anyer Km. 121, Gunung Sugih, Ciwandan, Banten | Q16: 1 | S16: 173000000 | T16: =+S16/U16 -> 720833.33 | U16: 240 | V16: 240 | W16: =+AB16/T16 -> 0 | X16: =+V16+W16 -> 240 | Y16: =+U16-X16 -> 0 | Z16: 1.73e+08 | AA16: -5.9604645e-08 | AB16: =SUM(AC16:AH16) -> 0 | AO16: =+Z16+AB16 -> 1.73e+08 | AP16: =IF(AR16=$AR$8,((S16-AO16)*0),S16-AO16) -> -5.9604645e-08 | AU16: Ok | AV16: =VLOOKUP(F16,[78]!D365FinOps_API_Table[[FixedAssetNumber]:[Department]],80,FALSE) -> #REF! | BL16: 3B-E-003
A17: =+A16+1 -> 8 | B17: JKTC | C17: D10 | D17: 152 | F17: BLD000018 | G17: 38980 | H17: Building | I17: 2 | J17: Workshop at Jababeka Cikarang | K17: Kawasan Industri Jababeka, Jl Industri Selatan 2 Blok JJ no. 6, Cikarang West Java | Q17: 1 | S17: 153336000 | T17: =+S17/U17 -> 638900 | U17: 240 | V17: 231 | W17: =+AB17/T17 -> 6 | X17: =+V17+W17 -> 237 | Y17: =+U17-X17 -> 3 | Z17: 147585900 | AA17: 5750100 | AB17: =SUM(AC17:AH17) -> 3833400 | AC17: 638900 | AD17: 638900 | AE17: 638900 | AF17: 638900 | AG17: 638900 | AH17: 638900 | AI17: 638900 | AJ17: 638900 | AK17: 638900 | AL17: 638900 | AM17: 638900 | AN17: 638900 | AO17: =+Z17+AB17 -> 151419300 | AP17: =IF(AR17=$AR$8,((S17-AO17)*0),S17-AO17) -> 1916700 | AU17: Ok | AV17: =VLOOKUP(F17,[78]!D365FinOps_API_Table[[FixedAssetNumber]:[Department]],80,FALSE) -> #REF!
A18: =+A17+1 -> 9 | B18: JKTC | C18: D10 | D18: 152 | F18: BLD000019 | G18: 38981 | H18: Building | I18: 2 | J18: Workshop at Jababeka Cikarang | K18: Kawasan Industri Jababeka, Jl Industri Selatan 2 Blok JJ no. 6, Cikarang West Java | Q18: 1 | S18: 727290000 | T18: =+S18/U18 -> 3030375 | U18: 240 | V18: 231 | W18: =+AB18/T18 -> 6 | X18: =+V18+W18 -> 237 | Y18: =+U18-X18 -> 3 | Z18: 700016625 | AA18: 27273375 | AB18: =SUM(AC18:AH18) -> 18182250 | AC18: 3030375 | AD18: 3030375 | AE18: 3030375 | AF18: 3030375 | AG18: 3030375 | AH18: 3030375 | AI18: 3030375 | AJ18: 3030375 | AK18: 3030375 | AL18: 3030375 | AM18: 3030375 | AN18: 3030375 | AO18: =+Z18+AB18 -> 718198875 | AP18: =IF(AR18=$AR$8,((S18-AO18)*0),S18-AO18) -> 9091125 | AU18: Ok | AV18: =VLOOKUP(F18,[78]!D365FinOps_API_Table[[FixedAssetNumber]:[Department]],80,FALSE) -> #REF!
A19: =+A18+1 -> 10 | B19: JKTC | C19: D10 | D19: 152 | F19: BLD000020 | G19: 39051 | H19: Building | I19: 125 | J19: Renovation of New Workshop at Cikarang | K19: Kawasan Industri Jababeka, Jl Industri Selatan 2 Blok JJ no. 6, Cikarang West Java | Q19: 1 | S19: 36100000 | T19: =+S19/U19 -> 150416.67 | U19: 240 | V19: 229 | W19: =+AB19/T19 -> 6 | X19: =+V19+W19 -> 235 | Y19: =+U19-X19 -> 5 | Z19: 34445417 | AA19: 1654583.3 | AB19: =SUM(AC19:AH19) -> 902500 | AC19: 150416.67 | AD19: 150416.67 | AE19: 150416.67 | AF19: 150416.67 | AG19: 150416.67 | AH19: 150416.67 | AI19: 150416.67 | AJ19: 150416.67 | AK19: 150416.67 | AL19: 150416.67 | AM19: 150416.67 | AN19: 150416.67 | AO19: =+Z19+AB19 -> 35347917 | AP19: =IF(AR19=$AR$8,((S19-AO19)*0),S19-AO19) -> 752083.33 | AU19: Ok | AV19: =VLOOKUP(F19,[78]!D365FinOps_API_Table[[FixedAssetNumber]:[Department]],80,FALSE) -> #REF!
A20: =+A19+1 -> 11 | B20: JKTC | C20: D10 | D20: 152 | F20: BLD000021 | G20: 39051 | H20: Building | I20: 4005 | J20: Renovation of New Workshop at Cikarang | K20: Kawasan Industri Jababeka, Jl Industri Selatan 2 Blok JJ no. 6, Cikarang West Java | Q20: 1 | S20: 24253500 | T20: =+S20/U20 -> 101056.25 | U20: 240 | V20: 229 | W20: =+AB20/T20 -> 6 | X20: =+V20+W20 -> 235 | Y20: =+U20-X20 -> 5 | Z20: 23141881 | AA20: 1111618.8 | AB20: =SUM(AC20:AH20) -> 606337.5 | AC20: 101056.25 | AD20: 101056.25 | AE20: 101056.25 | AF20: 101056.25 | AG20: 101056.25 | AH20: 101056.25 | AI20: 101056.25 | AJ20: 101056.25 | AK20: 101056.25 | AL20: 101056.25 | AM20: 101056.25 | AN20: 101056.25 | AO20: =+Z20+AB20 -> 23748219 | AP20: =IF(AR20=$AR$8,((S20-AO20)*0),S20-AO20) -> 505281.25 | AU20: Ok | AV20: =VLOOKUP(F20,[78]!D365FinOps_API_Table[[FixedAssetNumber]:[Department]],80,FALSE) -> #REF!
A21: =+A20+1 -> 12 | B21: JKTC | C21: D10 | D21: 152 | F21: BLD000022 | G21: 39051 | H21: Building | I21: 4058 | J21: Renovation of New Workshop at Cikarang | K21: Kawasan Industri Jababeka, Jl Industri Selatan 2 Blok JJ no. 6, Cikarang West Java | Q21: 1 | S21: 64080000 | T21: =+S21/U21 -> 267000 | U21: 240 | V21: 229 | W21: =+AB21/T21 -> 6 | X21: =+V21+W21 -> 235 | Y21: =+U21-X21 -> 5 | Z21: 61143000 | AA21: 2937000 | AB21: =SUM(AC21:AH21) -> 1602000 | AC21: 267000 | AD21: 267000 | AE21: 267000 | AF21: 267000 | AG21: 267000 | AH21: 267000 | AI21: 267000 | AJ21: 267000 | AK21: 267000 | AL21: 267000 | AM21: 267000 | AN21: 267000 | AO21: =+Z21+AB21 -> 62745000 | AP21: =IF(AR21=$AR$8,((S21-AO21)*0),S21-AO21) -> 1335000 | AU21: Ok | AV21: =VLOOKUP(F21,[78]!D365FinOps_API_Table[[FixedAssetNumber]:[Department]],80,FALSE) -> #REF!
A22: =+A21+1 -> 13 | B22: JKTC | C22: D10 | D22: 152 | F22: BLD000023 | G22: 39051 | H22: Building | I22: 4058 | J22: Renovation of New Workshop at Cikarang | K22: Kawasan Industri Jababeka, Jl Industri Selatan 2 Blok JJ no. 6, Cikarang West Java | Q22: 1 | S22: 42720000 | T22: =+S22/U22 -> 178000 | U22: 240 | V22: 229 | W22: =+AB22/T22 -> 6 | X22: =+V22+W22 -> 235 | Y22: =+U22-X22 -> 5 | Z22: 40762000 | AA22: 1958000 | AB22: =SUM(AC22:AH22) -> 1068000 | AC22: 178000 | AD22: 178000 | AE22: 178000 | AF22: 178000 | AG22: 178000 | AH22: 178000 | AI22: 178000 | AJ22: 178000 | AK22: 178000 | AL22: 178000 | AM22: 178000 | AN22: 178000 | AO22: =+Z22+AB22 -> 41830000 | AP22: =IF(AR22=$AR$8,((S22-AO22)*0),S22-AO22) -> 890000 | AU22: Ok | AV22: =VLOOKUP(F22,[78]!D365FinOps_API_Table[[FixedAssetNumber]:[Department]],80,FALSE) -> #REF!
A23: =+A22+1 -> 14 | B23: JKTC | C23: D10 | D23: 152 | F23: BLD000024 | G23: 39080 | H23: Building | I23: 4013 | J23: Additional work for New warehouse at Cikarang | K23: Kawasan Industri Jababeka, Jl Industri Selatan 2 Blok JJ no. 6, Cikarang West Java | Q23: 1 | S23: 22000000 | T23: =+S23/U23 -> 91666.667 | U23: 240 | V23: 229 | W23: =+AB23/T23 -> 6 | X23: =+V23+W23 -> 235 | Y23: =+U23-X23 -> 5 | Z23: 20991667 | AA23: 1008333.3 | AB23: =SUM(AC23:AH23) -> 550000 | AC23: 91666.667 | AD23: 91666.667 | AE23: 91666.667 | AF23: 91666.667 | AG23: 91666.667 | AH23: 91666.667 | AI23: 91666.667 | AJ23: 91666.667 | AK23: 91666.667 | AL23: 91666.667 | AM23: 91666.667 | AN23: 91666.667 | AO23: =+Z23+AB23 -> 21541667 | AP23: =IF(AR23=$AR$8,((S23-AO23)*0),S23-AO23) -> 458333.33 | AU23: Ok | AV23: =VLOOKUP(F23,[78]!D365FinOps_API_Table[[FixedAssetNumber]:[Department]],80,FALSE) -> #REF!
A24: =+A23+1 -> 15 | B24: JKTC | C24: D10 | D24: 152 | F24: BLD000025 | G24: 39080 | H24: Building | I24: 4029 | J24: Additional work for New warehouse at Cikarang | K24: Kawasan Industri Jababeka, Jl Industri Selatan 2 Blok JJ no. 6, Cikarang West Java | Q24: 1 | S24: 16169000 | T24: =+S24/U24 -> 67370.833 | U24: 240 | V24: 229 | W24: =+AB24/T24 -> 6 | X24: =+V24+W24 -> 235 | Y24: =+U24-X24 -> 5 | Z24: 15427921 | AA24: 741079.17 | AB24: =SUM(AC24:AH24) -> 404225 | AC24: 67370.833 | AD24: 67370.833 | AE24: 67370.833 | AF24: 67370.833 | AG24: 67370.833 | AH24: 67370.833 | AI24: 67370.833 | AJ24: 67370.833 | AK24: 67370.833 | AL24: 67370.833 | AM24: 67370.833 | AN24: 67370.833 | AO24: =+Z24+AB24 -> 15832146 | AP24: =IF(AR24=$AR$8,((S24-AO24)*0),S24-AO24) -> 336854.17 | AU24: Ok | AV24: =VLOOKUP(F24,[78]!D365FinOps_API_Table[[FixedAssetNumber]:[Department]],80,FALSE) -> #REF!
A25: =+A24+1 -> 16 | B25: JKTC | C25: D10 | D25: 152 | F25: BLD000026 | G25: 39080 | H25: Building | I25: 4033 | J25: Additional work for New warehouse at Cikarang | K25: Kawasan Industri Jababeka, Jl Industri Selatan 2 Blok JJ no. 6, Cikarang West Java | Q25: 1 | S25: 51901000 | T25: =+S25/U25 -> 216254.17 | U25: 240 | V25: 229 | W25: =+AB25/T25 -> 6 | X25: =+V25+W25 -> 235 | Y25: =+U25-X25 -> 5 | Z25: 49522204 | AA25: 2378795.8 | AB25: =SUM(AC25:AH25) -> 1297525 | AC25: 216254.17 | AD25: 216254.17 | AE25: 216254.17 | AF25: 216254.17 | AG25: 216254.17 | AH25: 216254.17 | AI25: 216254.17 | AJ25: 216254.17 | AK25: 216254.17 | AL25: 216254.17 | AM25: 216254.17 | AN25: 216254.17 | AO25: =+Z25+AB25 -> 50819729 | AP25: =IF(AR25=$AR$8,((S25-AO25)*0),S25-AO25) -> 1081270.8 | AU25: Ok | AV25: =VLOOKUP(F25,[78]!D365FinOps_API_Table[[FixedAssetNumber]:[Department]],80,FALSE) -> #REF!
A26: =+A25+1 -> 17 | B26: JKTC | C26: D10 | D26: 152 | F26: BLD000027 | G26: 39080 | H26: Building | I26: 4053 | J26: Additional work for New warehouse at Cikarang | K26: Kawasan Industri Jababeka, Jl Industri Selatan 2 Blok JJ no. 6, Cikarang West Java | Q26: 1 | S26: 37640000 | T26: =+S26/U26 -> 156833.33 | U26: 240 | V26: 229 | W26: =+AB26/T26 -> 6 | X26: =+V26+W26 -> 235 | Y26: =+U26-X26 -> 5 | Z26: 35914833 | AA26: 1725166.7 | AB26: =SUM(AC26:AH26) -> 941000 | AC26: 156833.33 | AD26: 156833.33 | AE26: 156833.33 | AF26: 156833.33 | AG26: 156833.33 | AH26: 156833.33 | AI26: 156833.33 | AJ26: 156833.33 | AK26: 156833.33 | AL26: 156833.33 | AM26: 156833.33 | AN26: 156833.33 | AO26: =+Z26+AB26 -> 36855833 | AP26: =IF(AR26=$AR$8,((S26-AO26)*0),S26-AO26) -> 784166.67 | AU26: Ok | AV26: =VLOOKUP(F26,[78]!D365FinOps_API_Table[[FixedAssetNumber]:[Department]],80,FALSE) -> #REF!
A27: =+A26+1 -> 18 | B27: JKTC | C27: D10 | D27: 152 | F27: BLD000028 | G27: 39113 | H27: Building | I27: 4022 | J27: Renovation of New Workshop at Cikarang | K27: Kawasan Industri Jababeka, Jl Industri Selatan 2 Blok JJ no. 6, Cikarang West Java | Q27: 1 | S27: 50340000 | T27: =+S27/U27 -> 209750 | U27: 240 | V27: 228 | W27: =+AB27/T27 -> 6 | X27: =+V27+W27 -> 234 | Y27: =+U27-X27 -> 6 | Z27: 47823000 | AA27: 2517000 | AB27: =SUM(AC27:AH27) -> 1258500 | AC27: 209750 | AD27: 209750 | AE27: 209750 | AF27: 209750 | AG27: 209750 | AH27: 209750 | AI27: 209750 | AJ27: 209750 | AK27: 209750 | AL27: 209750 | AM27: 209750 | AN27: 209750 | AO27: =+Z27+AB27 -> 49081500 | AP27: =IF(AR27=$AR$8,((S27-AO27)*0),S27-AO27) -> 1258500 | AU27: Ok | AV27: =VLOOKUP(F27,[78]!D365FinOps_API_Table[[FixedAssetNumber]:[Department]],80,FALSE) -> #REF!
A28: =+A27+1 -> 19 | B28: JKTC | C28: D10 | D28: 152 | F28: BLD000029 | G28: 39113 | H28: Building | I28: 4026 | J28: Renovation of New Workshop at Cikarang | K28: Kawasan Industri Jababeka, Jl Industri Selatan 2 Blok JJ no. 6, Cikarang West Java | Q28: 1 | S28: 23735290 | T28: =+S28/U28 -> 98897.042 | U28: 240 | V28: 228 | W28: =+AB28/T28 -> 6 | X28: =+V28+W28 -> 234 | Y28: =+U28-X28 -> 6 | Z28: 22548526 | AA28: 1186764.5 | AB28: =SUM(AC28:AH28) -> 593382.25 | AC28: 98897.042 | AD28: 98897.042 | AE28: 98897.042 | AF28: 98897.042 | AG28: 98897.042 | AH28: 98897.042 | AI28: 98897.042 | AJ28: 98897.042 | AK28: 98897.042 | AL28: 98897.042 | AM28: 98897.042 | AN28: 98897.042 | AO28: =+Z28+AB28 -> 23141908 | AP28: =IF(AR28=$AR$8,((S28-AO28)*0),S28-AO28) -> 593382.25 | AU28: Ok | AV28: =VLOOKUP(F28,[78]!D365FinOps_API_Table[[FixedAssetNumber]:[Department]],80,FALSE) -> #REF!
... A37: =+A36+1 -> 28 | B37: JKTC | C37: D10 | D37: 152 | F37: BLD000038 | G37: 39171 | H37: Building | I37: 4049 | J37: Renovation of New Workshop at Cikarang | K37: Kawasan Industri Jababeka, Jl Industri Selatan 2 Blok JJ no. 6, Cikarang West Java | Q37: 1 | S37: 13800000 | T37: =+S37/U37 -> 57500 | U37: 240 | V37: 226 | W37: =+AB37/T37 -> 6 | X37: =+V37+W37 -> 232 | Y37: =+U37-X37 -> 8 | Z37: 12995000 | AA37: 805000 | AB37: =SUM(AC37:AH37) -> 345000 | AC37: 57500 | AD37: 57500 | AE37: 57500 | AF37: 57500 | AG37: 57500 | AH37: 57500 | AI37: 57500 | AJ37: 57500 | AK37: 57500 | AL37: 57500 | AM37: 57500 | AN37: 57500 | AO37: =+Z37+AB37 -> 13340000 | AP37: =IF(AR37=$AR$8,((S37-AO37)*0),S37-AO37) -> 460000 | AU37: Ok | AV37: =VLOOKUP(F37,[78]!D365FinOps_API_Table[[FixedAssetNumber]:[Department]],80,FALSE) -> #REF!
A38: =+A37+1 -> 29 | B38: CLGA | C38: AD_CGADM | D38: 152 | E38: 7-E-008 | F38: BLD000039 | G38: 39660 | H38: Building | I38: 3051 | J38: New mess for Japanesse | K38: Jl. TB. Ismail, Bendungan, Cilegon, Banten | Q38: 1 | S38: 3000000000 | T38: =+S38/U38 -> 12500000 | U38: 240 | V38: 210 | W38: =+AB38/T38 -> 6 | X38: =+V38+W38 -> 216 | Y38: =+U38-X38 -> 24 | Z38: 2625000000 | AA38: 375000000 | AB38: =SUM(AC38:AH38) -> 75000000 | AC38: 12500000 | AD38: 12500000 | AE38: 12500000 | AF38: 12500000 | AG38: 12500000 | AH38: 12500000 | AI38: 12500000 | AJ38: 12500000 | AK38: 12500000 | AL38: 12500000 | AM38: 12500000 | AN38: 12500000 | AO38: =+Z38+AB38 -> 2700000000 | AP38: =IF(AR38=$AR$8,((S38-AO38)*0),S38-AO38) -> 300000000 | AU38: Ok | AV38: =VLOOKUP(F38,[78]!D365FinOps_API_Table[[FixedAssetNumber]:[Department]],80,FALSE) -> #REF! | BL38: 7-E-008
A39: =+A38+1 -> 30 | B39: CLGA | C39: AD_CGADM | D39: 152 | E39: 7C-E-002 | F39: BLD000040 | G39: 39660 | H39: Building | I39: 3052 | J39: Cilegon New Office | K39: Jl. Raya Anyer Km. 121, Gunung Sugih, Ciwandan, Banten | S39: 540406125 | T39: 2251692.2 | U39: 240 | V39: 210 | W39: =+AB39/T39 -> 6 | X39: =+V39+W39 -> 216 | Y39: =+U39-X39 -> 24 | Z39: 4.7285536e+08 | AA39: 67550766 | AB39: =SUM(AC39:AH39) -> 13510153 | AC39: 2251692.2 | AD39: 2251692.2 | AE39: 2251692.2 | AF39: 2251692.2 | AG39: 2251692.2 | AH39: 2251692.2 | AI39: 2251692.2 | AJ39: 2251692.2 | AK39: 2251692.2 | AL39: 2251692.2 | AM39: 2251692.2 | AN39: 2251692.2 | AO39: =+Z39+AB39 -> 4.8636551e+08 | AP39: =IF(AR39=$AR$8,((S39-AO39)*0),S39-AO39) -> 54040612 | AU39: Ok | AV39: =VLOOKUP(F39,[78]!D365FinOps_API_Table[[FixedAssetNumber]:[Department]],80,FALSE) -> #REF! | BL39: 7C-E-002
A40: =+A39+1 -> 31 | B40: CLGA | C40: AD_CGADM | D40: 152 | E40: 7C-E-002 | F40: BLD000041 | G40: 39660 | H40: Building | I40: 3052 | J40: Cilegon New Office | K40: Jl. Raya Anyer Km. 121, Gunung Sugih, Ciwandan, Banten | Q40: 1 | S40: 2161624500 | T40: 10132615 | U40: 240 | V40: 200.66667 | W40: =+AB40/T40 -> 6 | X40: =+V40+W40 -> 206.66667 | Y40: =+U40-X40 -> 33.333333 | Z40: 2.033278e+09 | AA40: 1.2834645e+08 | AB40: =SUM(AC40:AH40) -> 60795689 | AC40: 10132615 | AD40: 10132615 | AE40: 10132615 | AF40: 10132615 | AG40: 10132615 | AH40: 10132615 | AI40: 10132615 | AJ40: 10132615 | AK40: 10132615 | AL40: 10132615 | AM40: 10132615 | AN40: 10132615 | AO40: =+Z40+AB40 -> 2.0940737e+09 | AP40: =IF(AR40=$AR$8,((S40-AO40)*0),S40-AO40) -> 67550766 | AU40: Ok | AV40: =VLOOKUP(F40,[78]!D365FinOps_API_Table[[FixedAssetNumber]:[Department]],80,FALSE) -> #REF! | BL40: 7C-E-002
A41: =+A40+1 -> 32 | B41: CLGA | C41: AD_CGADM | D41: 152 | E41: 7C-E-002 | F41: BLD000042 | G41: 39660 | H41: Building | I41: 3052 | J41: Cilegon New Office | K41: Jl. Raya Anyer Km. 121, Gunung Sugih, Ciwandan, Banten | S41: 2702030625 | T41: 10132615 | U41: 240 | V41: 219.33333 | W41: =+AB41/T41 -> 6 | X41: =+V41+W41 -> 225.33333 | Y41: =+U41-X41 -> 14.666667 | Z41: 2.2224202e+09 | AA41: 4.7961044e+08 | AB41: =SUM(AC41:AH41) -> 60795689 | AC41: 10132615 | AD41: 10132615 | AE41: 10132615 | AF41: 10132615 | AG41: 10132615 | AH41: 10132615 | AI41: 10132615 | AJ41: 10132615 | AK41: 10132615 | AL41: 10132615 | AM41: 10132615 | AN41: 10132615 | AO41: =+Z41+AB41 -> 2.2832159e+09 | AP41: =IF(AR41=$AR$8,((S41-AO41)*0),S41-AO41) -> 4.1881475e+08 | AU41: Ok | AV41: =VLOOKUP(F41,[78]!D365FinOps_API_Table[[FixedAssetNumber]:[Department]],80,FALSE) -> #REF! | BL41: 7C-E-002
A42: =+A41+1 -> 33 | B42: JOIN | C42: D30 | D42: 152 | E42: 3B-E-004 | F42: BLD000043 | G42: 39717 | H42: Building | I42: 3041 | J42: Renovation for Warehouse Cilegon | K42: Jl. Raya Anyer Km. 121, Gunung Sugih, Ciwandan, Banten | Q42: 1 | S42: 114000000 | T42: =+S42/U42 -> 950000 | U42: 120 | V42: 120 | W42: =+AB42/T42 -> 0 | X42: =+V42+W42 -> 120 | Y42: =+U42-X42 -> 0 | Z42: 114000000 | AA42: 0 | AB42: =SUM(AC42:AH42) -> 0 | AO42: =+Z42+AB42 -> 114000000 | AP42: =IF(AR42=$AR$8,((S42-AO42)*0),S42-AO42) -> 0 | AU42: Ok | AV42: =VLOOKUP(F42,[78]!D365FinOps_API_Table[[FixedAssetNumber]:[Department]],80,FALSE) -> #REF! | BL42: 3B-E-004
A43: =+A42+1 -> 34 | B43: HCT | C43: D30 | D43: 152 | E43: 3B-E-004 | F43: BLD000044 | G43: 39717 | H43: Building | I43: 3041 | J43: Renovation for Warehouse Cilegon | K43: Jl. Raya Anyer Km. 121, Gunung Sugih, Ciwandan, Banten | S43: 456000000 | T43: =+S43/U43 -> 3800000 | U43: 120 | V43: 120 | W43: =+AB43/T43 -> 0 | X43: =+V43+W43 -> 120 | Y43: =+U43-X43 -> 0 | Z43: 456000000 | AA43: 0 | AB43: =SUM(AC43:AH43) -> 0 | AO43: =+Z43+AB43 -> 456000000 | AP43: =IF(AR43=$AR$8,((S43-AO43)*0),S43-AO43) -> 0 | AU43: Ok | AV43: =VLOOKUP(F43,[78]!D365FinOps_API_Table[[FixedAssetNumber]:[Department]],80,FALSE) -> #REF! | BL43: 3B-E-004
A44: =+A43+1 -> 35 | B44: CLGC | C44: D30 | D44: 152 | E44: M10-E-003 | F44: BLD000045 | G44: 40907 | H44: Building | I44: 3031 | J44: Warehouse Canopy | K44: Jl. Raya Anyer Km. 121, Gunung Sugih, Ciwandan, Banten | Q44: 1 | S44: 950000000 | T44: =+S44/U44 -> 15833333 | U44: 60 | V44: 60 | W44: =+AB44/T44 -> 0 | X44: =+V44+W44 -> 60 | Y44: =+U44-X44 -> 0 | Z44: 950000000 | AA44: 0 | AB44: =SUM(AC44:AH44) -> 0 | AO44: =+Z44+AB44 -> 950000000 | AP44: =IF(AR44=$AR$8,((S44-AO44)*0),S44-AO44) -> 0 | AU44: Ok | AV44: =VLOOKUP(F44,[78]!D365FinOps_API_Table[[FixedAssetNumber]:[Department]],80,FALSE) -> #REF! | BG44: 1 | BL44: M10-E-003
A45: =+A44+1 -> 36 | B45: SLI | C45: AD_HO | D45: 152 | E45: JKL-131-001 | F45: BLD000046 | G45: 41163 | H45: Building | I45: 5 | J45: Tanjung Priok Office | K45: Jl. Enggano no. 40B Jakarta Utara | L45: Jakarta Logistic | M45: 2012 | Q45: 1 | S45: 570190000 | T45: =+S45/U45 -> 2375791.7 | U45: 240 | V45: 162 | W45: =+AB45/T45 -> 6 | X45: =+V45+W45 -> 168 | Y45: =+U45-X45 -> 72 | Z45: 384878250 | AA45: 185311750 | AB45: =SUM(AC45:AH45) -> 14254750 | AC45: 2375791.7 | AD45: 2375791.7 | AE45: 2375791.7 | AF45: 2375791.7 | AG45: 2375791.7 | AH45: 2375791.7 | AI45: 2375791.7 | AJ45: 2375791.7 | AK45: 2375791.7 | AL45: 2375791.7 | AM45: 2375791.7 | AN45: 2375791.7 | AO45: =+Z45+AB45 -> 399133000 | AP45: =IF(AR45=$AR$8,((S45-AO45)*0),S45-AO45) -> 171057000 | AU45: Ok | AV45: =VLOOKUP(F45,[78]!D365FinOps_API_Table[[FixedAssetNumber]:[Department]],80,FALSE) -> #REF! | BL45: JKL-131-001
A46: =+A45+1 -> 37 | B46: CKR | C46: AD_HO | D46: 152 | E46: BLD000047 | F46: BLD000047 | G46: 41639 | H46: Building | I46: 111 | J46: Cikarang Warehouse and Office | K46: Kawasan Industri Terpadu Indonesia China (KITIC) Kav. 20, Cikarang, West Java | L46: Head Ofice & Cikarang Logistic | M46: 2013 | Q46: 1 | S46: 17412922966 | T46: =+S46/U46 -> 72553846 | U46: 240 | V46: 145 | W46: =+AB46/T46 -> 6 | X46: =+V46+W46 -> 151 | Y46: =+U46-X46 -> 89 | Z46: 1.0520308e+10 | AA46: 6.8926153e+09 | AB46: =SUM(AC46:AH46) -> 4.3532307e+08 | AC46: 72553846 | AD46: 72553846 | AE46: 72553846 | AF46: 72553846 | AG46: 72553846 | AH46: 72553846 | AI46: 72553846 | AJ46: 72553846 | AK46: 72553846 | AL46: 72553846 | AM46: 72553846 | AN46: 72553846 | AO46: =+Z46+AB46 -> 1.0955631e+10 | AP46: =IF(AR46=$AR$8,((S46-AO46)*0),S46-AO46) -> 6.4572923e+09 | AU46: Ok | AV46: =VLOOKUP(F46,[78]!D365FinOps_API_Table[[FixedAssetNumber]:[Department]],80,FALSE) -> #REF! | BL46: BLD000047
A47: =+A46+1 -> 38 | B47: CLC | C47: CLCWH | D47: 152 | E47: CLC131-001 | F47: BLD000048 | G47: 41639 | H47: Building | I47: 111 | J47: Cikarang Warehouse and Office | K47: Kawasan Industri Terpadu Indonesia China (KITIC) Kav. 20, Cikarang, West Java | L47: Head Ofice & Cikarang Logistic | M47: 2013 | Q47: 1 | S47: 7.1701319e+10 | T47: =+S47/U47 -> 2.987555e+08 | U47: 240 | V47: 145 | W47: =+AB47/T47 -> 6 | X47: =+V47+W47 -> 151 | Y47: =+U47-X47 -> 89 | Z47: 4.3319547e+10 | AA47: 2.8381772e+10 | AB47: =SUM(AC47:AH47) -> 1.792533e+09 | AC47: 2.987555e+08 | AD47: 2.987555e+08 | AE47: 2.987555e+08 | AF47: 2.987555e+08 | AG47: 2.987555e+08 | AH47: 2.987555e+08 | AI47: 2.987555e+08 | AJ47: 2.987555e+08 | AK47: 2.987555e+08 | AL47: 2.987555e+08 | AM47: 2.987555e+08 | AN47: 2.987555e+08 | AO47: =+Z47+AB47 -> 4.511208e+10 | AP47: =IF(AR47=$AR$8,((S47-AO47)*0),S47-AO47) -> 2.6589239e+10 | AU47: Ok | AV47: =VLOOKUP(F47,[78]!D365FinOps_API_Table[[FixedAssetNumber]:[Department]],80,FALSE) -> #REF! | AW47: =AV47-AJ47 -> #REF! | BL47: CLC131-001
A48: =+A47+1 -> 39 | B48: CLGC | C48: D30 | D48: 152 | E48: M10-E-004 | F48: BLD000049 | G48: 41696 | H48: Building | I48: 3152 | J48: Fencing | K48: Bojonegara Land | M48: 2014 | Q48: 1 | S48: 1129260000 | T48: =+S48/U48 -> 18821000 | U48: 60 | V48: 60 | W48: =+AB48/T48 -> 0 | X48: =+V48+W48 -> 60 | Y48: =+U48-X48 -> 0 | Z48: 1129260000 | AA48: 0 | AB48: =SUM(AC48:AH48) -> 0 | AO48: =+Z48+AB48 -> 1129260000 | AP48: =IF(AR48=$AR$8,((S48-AO48)*0),S48-AO48) -> 0 | AU48: Ok | AV48: =VLOOKUP(F48,[78]!D365FinOps_API_Table[[FixedAssetNumber]:[Department]],80,FALSE) -> #REF! | AW48: =AV48-AJ48 -> #REF! | BL48: M10-E-004
A49: =+A48+1 -> 40 | B49: CLGC | C49: D30 | D49: 152 | E49: M10-E-005 | F49: BLD000050 | G49: 41757 | H49: Building | I49: 13 | J49: Clearing and compacting Land at Bojonegara | M49: 2014 | Q49: 1 | S49: 1167000000 | T49: =+S49/U49 -> 19450000 | U49: 60 | V49: 60 | W49: =+AB49/T49 -> 0 | X49: =+V49+W49 -> 60 | Y49: =+U49-X49 -> 0 | Z49: 1167000000 | AA49: 0 | AB49: =SUM(AC49:AH49) -> 0 | AO49: =+Z49+AB49 -> 1167000000 | AP49: =IF(AR49=$AR$8,((S49-AO49)*0),S49-AO49) -> 0 | AU49: Ok | AV49: =VLOOKUP(F49,[78]!D365FinOps_API_Table[[FixedAssetNumber]:[Department]],80,FALSE) -> #REF! | AW49: =AV49-AJ49 -> #REF! | BL49: M10-E-005
A50: =+A49+1 -> 41 | B50: CLGC | C50: D30 | D50: 152 | E50: M10-E-005 | F50: BLD000051 | G50: 41757 | H50: Building | I50: 13 | J50: Clearing and compacting Land at Bojonegara | M50: 2014 | S50: 1167000000 | T50: =+S50/U50 -> 19450000 | U50: 60 | V50: 60 | W50: =+AB50/T50 -> 0 | X50: =+V50+W50 -> 60 | Y50: =+U50-X50 -> 0 | Z50: 1167000000 | AA50: 0 | AB50: =SUM(AC50:AH50) -> 0 | AO50: =+Z50+AB50 -> 1167000000 | AP50: =IF(AR50=$AR$8,((S50-AO50)*0),S50-AO50) -> 0 | AU50: Ok | AV50: =VLOOKUP(F50,[78]!D365FinOps_API_Table[[FixedAssetNumber]:[Department]],80,FALSE) -> #REF! | AW50: =AV50-AJ50 -> #REF! | BL50: M10-E-005
...

Sheet Sheet1
D4: Land | E4: 7 Location
D5: Buildings | E5: 78 Office and Workshop
D6: Structures | E6: 61 Structure
D7: Machinery & Equipments | E7: 278 Machine & Equipment
D8: Vehicles | E8: 474 Vehicle
D9: Tools, Furnitures & Fixtures | E9: 181 Tools & Furnitur
D10: Non-Asset | E10: 88 Item Machine, Tools and Vehicle

Sheet Disposal 2026
A1: PT. Sankyu Indonesia International
A2: Disposals of Fixed Asset
A3: =TOTAL!A3 -> 30 Jun 2026
A6: No | B6: Name of Asset | C6: Fix Asset Number AX | D6: Maker/Type/Location | E6: Capacity | F6: Police No. | G6: Machine No. | H6: Chasis No. | I6: Site | J6: Job | K6: Date | M6: Purchase | N6: Acc. Depr. | O6: Net Book Value | P6: Proceed | Q6: Gain on Sale | R6: Lose on Sale | T6: Vc. | U6: Buyer
K7: Purchase | L7: Disposal | M7: Price | N7: upto Disposal | Q7: ( 421 ) | R7: ( 521 )
A9: 1 | B9: =IF(IFERROR(VLOOKUP(C9,FA_2026!$F$10:$AT$65451,5,FALSE),0)=0,"-",IFERROR(VLOOKUP(C9,FA_2026!$F$10:$AT$65451,5,FALSE),0)) -> Lightening Rod | C9: MNE000202 | D9: =IF(IFERROR(VLOOKUP(C9,FA_2026!$F$10:$AT$65451,6,FALSE),0)=0,"-",IFERROR(VLOOKUP(C9,FA_2026!$F$10:$AT$65451,6,FALSE),0)) -> Joko | E9: =IF(IFERROR(VLOOKUP(C9,FA_2026!$F$10:$AT$65451,7,FALSE),0)=0,"-",IFERROR(VLOOKUP(C9,FA_2026!$F$10:$AT$65451,7,FALSE),0)) -> WH Surabaya | F9: =IF(IFERROR(VLOOKUP(C9,FA_2026!$F$10:$AT$65451,9,FALSE),0)=0,"-",IFERROR(VLOOKUP(C9,FA_2026!$F$10:$AT$65451,9,FALSE),0)) -> - | G9: =IF(IFERROR(VLOOKUP(C9,FA_2026!$F$10:$AT$65451,10,FALSE),0)=0,"-",IFERROR(VLOOKUP(C9,FA_2026!$F$10:$AT$65451,10,FALSE),0)) -> - | H9: =IF(IFERROR(VLOOKUP(C9,FA_2026!$F$10:$AT$65451,11,FALSE),0)=0,"-",IFERROR(VLOOKUP(C9,FA_2026!$F$10:$AT$65451,11,FALSE),0)) -> - | I9: =IFERROR(INDEX(FA_2026!$B$10:$B$1159,MATCH('Disposal 2026'!C9,FA_2026!$F$10:$F$1159,0)),0) -> CLC | J9: =IFERROR(INDEX(FA_2026!$C$10:$C$1159,MATCH('Disposal 2026'!C9,FA_2026!$F$10:$F$1159,0)),0) -> CLCWH | K9: =IF(IFERROR(VLOOKUP(C9,FA_2026!$F$10:$AT$65451,2,FALSE),0)=0,"-",IFERROR(VLOOKUP(C9,FA_2026!$F$10:$AT$65451,2,FALSE),0)) -> 42338 | L9: =IF(IFERROR(VLOOKUP(C9,'List Approval 2025'!$D$7:$M$65624,5,FALSE),0)=0,"-",IFERROR(VLOOKUP(C9,'List Approval 2025'!$D$7:$M$65624,5,FALSE),0)) -> - | M9: =IF(IFERROR(VLOOKUP(C9,FA_2026!$F$10:$AT$65451,14,FALSE),0)=0,"-",IFERROR(VLOOKUP(C9,FA_2026!$F$10:$AT$65451,14,FALSE),0)) -> 17300000 | N9: =IF(IFERROR(VLOOKUP(C9,FA_2026!$F$10:$AT$65451,36,FALSE),0)=0,"-",IFERROR(VLOOKUP(C9,FA_2026!$F$10:$AT$65451,36,FALSE),0)) -> 17300000 | O9: =ROUND(IFERROR(+M9-N9,0),0) -> 0 | P9: =IFERROR(VLOOKUP(C9,'List Approval 2026'!$D$7:$M$276,10,FALSE),0) -> 0 | Q9: =(IFERROR(IF(+P9-O9<0,"-",+P9-O9),0)) -> 0 | R9: =(IFERROR(IF(P9-O9>=0,"-",O9-P9),0)) -> - | U9: =IFERROR(VLOOKUP(C9,'List Approval 2026'!$D$7:$P$225,13,FALSE),"-") -> Sankyu CLC
A10: =+A9+1 -> 2 | B10: =IF(IFERROR(VLOOKUP(C10,FA_2026!$F$10:$AT$65451,5,FALSE),0)=0,"-",IFERROR(VLOOKUP(C10,FA_2026!$F$10:$AT$65451,5,FALSE),0)) -> Crowler Crane | C10: VEH000054 | D10: =IF(IFERROR(VLOOKUP(C10,FA_2026!$F$10:$AT$65451,6,FALSE),0)=0,"-",IFERROR(VLOOKUP(C10,FA_2026!$F$10:$AT$65451,6,FALSE),0)) -> Sumitomo | E10: =IF(IFERROR(VLOOKUP(C10,FA_2026!$F$10:$AT$65451,7,FALSE),0)=0,"-",IFERROR(VLOOKUP(C10,FA_2026!$F$10:$AT$65451,7,FALSE),0)) -> 200T | F10: =IF(IFERROR(VLOOKUP(C10,FA_2026!$F$10:$AT$65451,9,FALSE),0)=0,"-",IFERROR(VLOOKUP(C10,FA_2026!$F$10:$AT$65451,9,FALSE),0)) -> - | G10: =IF(IFERROR(VLOOKUP(C10,FA_2026!$F$10:$AT$65451,10,FALSE),0)=0,"-",IFERROR(VLOOKUP(C10,FA_2026!$F$10:$AT$65451,10,FALSE),0)) -> K13C-TJ10782 | H10: =IF(IFERROR(VLOOKUP(C10,FA_2026!$F$10:$AT$65451,11,FALSE),0)=0,"-",IFERROR(VLOOKUP(C10,FA_2026!$F$10:$AT$65451,11,FALSE),0)) -> - | I10: =IFERROR(INDEX(FA_2026!$B$10:$B$1159,MATCH('Disposal 2026'!C10,FA_2026!$F$10:$F$1159,0)),0) -> CLGC | J10: =IFERROR(INDEX(FA_2026!$C$10:$C$1159,MATCH('Disposal 2026'!C10,FA_2026!$F$10:$F$1159,0)),0) -> D30 | K10: =IF(IFERROR(VLOOKUP(C10,FA_2026!$F$10:$AT$65451,2,FALSE),0)=0,"-",IFERROR(VLOOKUP(C10,FA_2026!$F$10:$AT$65451,2,FALSE),0)) -> 38228 | L10: =IF(IFERROR(VLOOKUP(C10,'List Approval 2025'!$D$7:$M$65624,5,FALSE),0)=0,"-",IFERROR(VLOOKUP(C10,'List Approval 2025'!$D$7:$M$65624,5,FALSE),0)) -> 1 | M10: =IF(IFERROR(VLOOKUP(C10,FA_2026!$F$10:$AT$65451,14,FALSE),0)=0,"-",IFERROR(VLOOKUP(C10,FA_2026!$F$10:$AT$65451,14,FALSE),0)) -> 7634037281 | N10: =IF(IFERROR(VLOOKUP(C10,FA_2026!$F$10:$AT$65451,36,FALSE),0)=0,"-",IFERROR(VLOOKUP(C10,FA_2026!$F$10:$AT$65451,36,FALSE),0)) -> 7634037281 | O10: =ROUND(IFERROR(+M10-N10,0),0) -> 0 | P10: =IFERROR(VLOOKUP(C10,'List Approval 2025'!$D$7:$M$277,10,FALSE),0) -> 1400000000 | Q10: =(IFERROR(IF(+P10-O10<0,"-",+P10-O10),0)) -> 1400000000 | R10: =(IFERROR(IF(P10-O10>=0,"-",O10-P10),0)) -> - | U10: =IFERROR(VLOOKUP(C10,'List Approval 2025'!$D$7:$P$226,13,FALSE),"-") -> - | V10: CAJE
A11: =+A10+1 -> 3 | B11: =IF(IFERROR(VLOOKUP(C11,FA_2026!$F$10:$AT$65451,5,FALSE),0)=0,"-",IFERROR(VLOOKUP(C11,FA_2026!$F$10:$AT$65451,5,FALSE),0)) -> Chassis High Bed | C11: VEH000083 | D11: =IF(IFERROR(VLOOKUP(C11,FA_2026!$F$10:$AT$65451,6,FALSE),0)=0,"-",IFERROR(VLOOKUP(C11,FA_2026!$F$10:$AT$65451,6,FALSE),0)) -> Masana (for Nissan) | E11: =IF(IFERROR(VLOOKUP(C11,FA_2026!$F$10:$AT$65451,7,FALSE),0)=0,"-",IFERROR(VLOOKUP(C11,FA_2026!$F$10:$AT$65451,7,FALSE),0)) -> 40 feet; 3 axcle | F11: =IF(IFERROR(VLOOKUP(C11,FA_2026!$F$10:$AT$65451,9,FALSE),0)=0,"-",IFERROR(VLOOKUP(C11,FA_2026!$F$10:$AT$65451,9,FALSE),0)) -> MS-04 | G11: =IF(IFERROR(VLOOKUP(C11,FA_2026!$F$10:$AT$65451,10,FALSE),0)=0,"-",IFERROR(VLOOKUP(C11,FA_2026!$F$10:$AT$65451,10,FALSE),0)) -> - | H11: =IF(IFERROR(VLOOKUP(C11,FA_2026!$F$10:$AT$65451,11,FALSE),0)=0,"-",IFERROR(VLOOKUP(C11,FA_2026!$F$10:$AT$65451,11,FALSE),0)) -> MTR0605128443 | I11: =IFERROR(INDEX(FA_2026!$B$10:$B$1159,MATCH('Disposal 2026'!C11,FA_2026!$F$10:$F$1159,0)),0) -> CLC | J11: =IFERROR(INDEX(FA_2026!$C$10:$C$1159,MATCH('Disposal 2026'!C11,FA_2026!$F$10:$F$1159,0)),0) -> CLCTRP | K11: =IF(IFERROR(VLOOKUP(C11,FA_2026!$F$10:$AT$65451,2,FALSE),0)=0,"-",IFERROR(VLOOKUP(C11,FA_2026!$F$10:$AT$65451,2,FALSE),0)) -> 38548 | L11: =IF(IFERROR(VLOOKUP(C11,'List Approval 2025'!$D$7:$M$65624,5,FALSE),0)=0,"-",IFERROR(VLOOKUP(C11,'List Approval 2025'!$D$7:$M$65624,5,FALSE),0)) -> - | M11: =IF(IFERROR(VLOOKUP(C11,FA_2026!$F$10:$AT$65451,14,FALSE),0)=0,"-",IFERROR(VLOOKUP(C11,FA_2026!$F$10:$AT$65451,14,FALSE),0)) -> 105000000 | N11: =IF(IFERROR(VLOOKUP(C11,FA_2026!$F$10:$AT$65451,36,FALSE),0)=0,"-",IFERROR(VLOOKUP(C11,FA_2026!$F$10:$AT$65451,36,FALSE),0)) -> 105000000 | O11: =ROUND(IFERROR(+M11-N11,0),0) -> 0 | P11: =IFERROR(VLOOKUP(C11,'List Approval 2026'!$D$7:$M$276,10,FALSE),0) -> 45045045 | Q11: =(IFERROR(IF(+P11-O11<0,"-",+P11-O11),0)) -> 45045045 | R11: =(IFERROR(IF(P11-O11>=0,"-",O11-P11),0)) -> - | U11: =IFERROR(VLOOKUP(C11,'List Approval 2026'!$D$7:$P$225,13,FALSE),"-") -> Citra Seraya Pratama
A12: =+A11+1 -> 4 | B12: =IF(IFERROR(VLOOKUP(C12,FA_2026!$F$10:$AT$65451,5,FALSE),0)=0,"-",IFERROR(VLOOKUP(C12,FA_2026!$F$10:$AT$65451,5,FALSE),0)) -> Head Tractor | C12: VEH000211 | D12: =IF(IFERROR(VLOOKUP(C12,FA_2026!$F$10:$AT$65451,6,FALSE),0)=0,"-",IFERROR(VLOOKUP(C12,FA_2026!$F$10:$AT$65451,6,FALSE),0)) -> Hino | E12: =IF(IFERROR(VLOOKUP(C12,FA_2026!$F$10:$AT$65451,7,FALSE),0)=0,"-",IFERROR(VLOOKUP(C12,FA_2026!$F$10:$AT$65451,7,FALSE),0)) -> 26T | F12: =IF(IFERROR(VLOOKUP(C12,FA_2026!$F$10:$AT$65451,9,FALSE),0)=0,"-",IFERROR(VLOOKUP(C12,FA_2026!$F$10:$AT$65451,9,FALSE),0)) -> A 9155 TZ | G12: =IF(IFERROR(VLOOKUP(C12,FA_2026!$F$10:$AT$65451,10,FALSE),0)=0,"-",IFERROR(VLOOKUP(C12,FA_2026!$F$10:$AT$65451,10,FALSE),0)) -> P11CUBJ-15323 | H12: =IF(IFERROR(VLOOKUP(C12,FA_2026!$F$10:$AT$65451,11,FALSE),0)=0,"-",IFERROR(VLOOKUP(C12,FA_2026!$F$10:$AT$65451,11,FALSE),0)) -> MJEFM2PKKCJZ-14141 | I12: =IFERROR(INDEX(FA_2026!$B$10:$B$1159,MATCH('Disposal 2026'!C12,FA_2026!$F$10:$F$1159,0)),0) -> CLC | J12: =IFERROR(INDEX(FA_2026!$C$10:$C$1159,MATCH('Disposal 2026'!C12,FA_2026!$F$10:$F$1159,0)),0) -> CLCTRP | K12: =IF(IFERROR(VLOOKUP(C12,FA_2026!$F$10:$AT$65451,2,FALSE),0)=0,"-",IFERROR(VLOOKUP(C12,FA_2026!$F$10:$AT$65451,2,FALSE),0)) -> 41016 | L12: =IF(IFERROR(VLOOKUP(C12,'List Approval 2025'!$D$7:$M$65624,5,FALSE),0)=0,"-",IFERROR(VLOOKUP(C12,'List Approval 2025'!$D$7:$M$65624,5,FALSE),0)) -> - | M12: =IF(IFERROR(VLOOKUP(C12,FA_2026!$F$10:$AT$65451,14,FALSE),0)=0,"-",IFERROR(VLOOKUP(C12,FA_2026!$F$10:$AT$65451,14,FALSE),0)) -> 832727273 | N12: =IF(IFERROR(VLOOKUP(C12,FA_2026!$F$10:$AT$65451,36,FALSE),0)=0,"-",IFERROR(VLOOKUP(C12,FA_2026!$F$10:$AT$65451,36,FALSE),0)) -> 8.3272727e+08 | O12: =ROUND(IFERROR(+M12-N12,0),0) -> 0 | P12: =IFERROR(VLOOKUP(C12,'List Approval 2026'!$D$7:$M$276,10,FALSE),0) -> 211711712 | Q12: =(IFERROR(IF(+P12-O12<0,"-",+P12-O12),0)) -> 211711712 | R12: =(IFERROR(IF(P12-O12>=0,"-",O12-P12),0)) -> - | U12: =IFERROR(VLOOKUP(C12,'List Approval 2026'!$D$7:$P$225,13,FALSE),"-") -> Citra Seraya Pratama
A13: =+A12+1 -> 5 | B13: =IF(IFERROR(VLOOKUP(C13,FA_2026!$F$10:$AT$65451,5,FALSE),0)=0,"-",IFERROR(VLOOKUP(C13,FA_2026!$F$10:$AT$65451,5,FALSE),0)) -> Forklift Sumitomo | C13: VEH000290 | D13: =IF(IFERROR(VLOOKUP(C13,FA_2026!$F$10:$AT$65451,6,FALSE),0)=0,"-",IFERROR(VLOOKUP(C13,FA_2026!$F$10:$AT$65451,6,FALSE),0)) -> Sumitomo | E13: =IF(IFERROR(VLOOKUP(C13,FA_2026!$F$10:$AT$65451,7,FALSE),0)=0,"-",IFERROR(VLOOKUP(C13,FA_2026!$F$10:$AT$65451,7,FALSE),0)) -> 1,5T | F13: =IF(IFERROR(VLOOKUP(C13,FA_2026!$F$10:$AT$65451,9,FALSE),0)=0,"-",IFERROR(VLOOKUP(C13,FA_2026!$F$10:$AT$65451,9,FALSE),0)) -> - | G13: =IF(IFERROR(VLOOKUP(C13,FA_2026!$F$10:$AT$65451,10,FALSE),0)=0,"-",IFERROR(VLOOKUP(C13,FA_2026!$F$10:$AT$65451,10,FALSE),0)) -> U2283 | H13: =IF(IFERROR(VLOOKUP(C13,FA_2026!$F$10:$AT$65451,11,FALSE),0)=0,"-",IFERROR(VLOOKUP(C13,FA_2026!$F$10:$AT$65451,11,FALSE),0)) -> R1H-04425 | I13: =IFERROR(INDEX(FA_2026!$B$10:$B$1159,MATCH('Disposal 2026'!C13,FA_2026!$F$10:$F$1159,0)),0) -> CLC | J13: =IFERROR(INDEX(FA_2026!$C$10:$C$1159,MATCH('Disposal 2026'!C13,FA_2026!$F$10:$F$1159,0)),0) -> CLCWH | K13: =IF(IFERROR(VLOOKUP(C13,FA_2026!$F$10:$AT$65451,2,FALSE),0)=0,"-",IFERROR(VLOOKUP(C13,FA_2026!$F$10:$AT$65451,2,FALSE),0)) -> 41715 | L13: =IF(IFERROR(VLOOKUP(C13,'List Approval 2025'!$D$7:$M$65624,5,FALSE),0)=0,"-",IFERROR(VLOOKUP(C13,'List Approval 2025'!$D$7:$M$65624,5,FALSE),0)) -> - | M13: =IF(IFERROR(VLOOKUP(C13,FA_2026!$F$10:$AT$65451,14,FALSE),0)=0,"-",IFERROR(VLOOKUP(C13,FA_2026!$F$10:$AT$65451,14,FALSE),0)) -> 253184243 | N13: =IF(IFERROR(VLOOKUP(C13,FA_2026!$F$10:$AT$65451,36,FALSE),0)=0,"-",IFERROR(VLOOKUP(C13,FA_2026!$F$10:$AT$65451,36,FALSE),0)) -> 253184243 | O13: =ROUND(IFERROR(+M13-N13,0),0) -> 0 | P13: =IFERROR(VLOOKUP(C13,'List Approval 2026'!$D$7:$M$276,10,FALSE),0) -> 15765766 | Q13: =(IFERROR(IF(+P13-O13<0,"-",+P13-O13),0)) -> 15765766 | R13: =(IFERROR(IF(P13-O13>=0,"-",O13-P13),0)) -> - | U13: =IFERROR(VLOOKUP(C13,'List Approval 2026'!$D$7:$P$225,13,FALSE),"-") -> Najwa Jaya
A14: =+A13+1 -> 6 | B14: =IF(IFERROR(VLOOKUP(C14,FA_2026!$F$10:$AT$65451,5,FALSE),0)=0,"-",IFERROR(VLOOKUP(C14,FA_2026!$F$10:$AT$65451,5,FALSE),0)) -> Pick Up | C14: VEH000300 | D14: =IF(IFERROR(VLOOKUP(C14,FA_2026!$F$10:$AT$65451,6,FALSE),0)=0,"-",IFERROR(VLOOKUP(C14,FA_2026!$F$10:$AT$65451,6,FALSE),0)) -> Daihatsu Grand Max | E14: =IF(IFERROR(VLOOKUP(C14,FA_2026!$F$10:$AT$65451,7,FALSE),0)=0,"-",IFERROR(VLOOKUP(C14,FA_2026!$F$10:$AT$65451,7,FALSE),0)) -> 2,1T | F14: =IF(IFERROR(VLOOKUP(C14,FA_2026!$F$10:$AT$65451,9,FALSE),0)=0,"-",IFERROR(VLOOKUP(C14,FA_2026!$F$10:$AT$65451,9,FALSE),0)) -> B 9971 SYM | G14: =IF(IFERROR(VLOOKUP(C14,FA_2026!$F$10:$AT$65451,10,FALSE),0)=0,"-",IFERROR(VLOOKUP(C14,FA_2026!$F$10:$AT$65451,10,FALSE),0)) -> DEH7723 | H14: =IF(IFERROR(VLOOKUP(C14,FA_2026!$F$10:$AT$65451,11,FALSE),0)=0,"-",IFERROR(VLOOKUP(C14,FA_2026!$F$10:$AT$65451,11,FALSE),0)) -> MHKP3CA1JEK056935 | I14: =IFERROR(INDEX(FA_2026!$B$10:$B$1159,MATCH('Disposal 2026'!C14,FA_2026!$F$10:$F$1159,0)),0) -> CLC | J14: =IFERROR(INDEX(FA_2026!$C$10:$C$1159,MATCH('Disposal 2026'!C14,FA_2026!$F$10:$F$1159,0)),0) -> CLCTRP | K14: =IF(IFERROR(VLOOKUP(C14,FA_2026!$F$10:$AT$65451,2,FALSE),0)=0,"-",IFERROR(VLOOKUP(C14,FA_2026!$F$10:$AT$65451,2,FALSE),0)) -> 41768 | L14: =IF(IFERROR(VLOOKUP(C14,'List Approval 2025'!$D$7:$M$65624,5,FALSE),0)=0,"-",IFERROR(VLOOKUP(C14,'List Approval 2025'!$D$7:$M$65624,5,FALSE),0)) -> 2 | M14: =IF(IFERROR(VLOOKUP(C14,FA_2026!$F$10:$AT$65451,14,FALSE),0)=0,"-",IFERROR(VLOOKUP(C14,FA_2026!$F$10:$AT$65451,14,FALSE),0)) -> 110400000 | N14: =IF(IFERROR(VLOOKUP(C14,FA_2026!$F$10:$AT$65451,36,FALSE),0)=0,"-",IFERROR(VLOOKUP(C14,FA_2026!$F$10:$AT$65451,36,FALSE),0)) -> 110400000 | O14: =ROUND(IFERROR(+M14-N14,0),0) -> 0 | P14: =IFERROR(VLOOKUP(C14,'List Approval 2025'!$D$7:$M$277,10,FALSE),0) -> 36036036 | Q14: =(IFERROR(IF(+P14-O14<0,"-",+P14-O14),0)) -> 36036036 | R14: =(IFERROR(IF(P14-O14>=0,"-",O14-P14),0)) -> - | U14: =IFERROR(VLOOKUP(C14,'List Approval 2025'!$D$7:$P$226,13,FALSE),"-") -> CV. TIRTO KENCONO | V14: 2025
A15: =+A14+1 -> 7 | B15: =IF(IFERROR(VLOOKUP(C15,FA_2026!$F$10:$AT$65451,5,FALSE),0)=0,"-",IFERROR(VLOOKUP(C15,FA_2026!$F$10:$AT$65451,5,FALSE),0)) -> Reach Truck Forklift | C15: VEH000372 | D15: =IF(IFERROR(VLOOKUP(C15,FA_2026!$F$10:$AT$65451,6,FALSE),0)=0,"-",IFERROR(VLOOKUP(C15,FA_2026!$F$10:$AT$65451,6,FALSE),0)) -> Toyota | E15: =IF(IFERROR(VLOOKUP(C15,FA_2026!$F$10:$AT$65451,7,FALSE),0)=0,"-",IFERROR(VLOOKUP(C15,FA_2026!$F$10:$AT$65451,7,FALSE),0)) -> 1,8 T | F15: =IF(IFERROR(VLOOKUP(C15,FA_2026!$F$10:$AT$65451,9,FALSE),0)=0,"-",IFERROR(VLOOKUP(C15,FA_2026!$F$10:$AT$65451,9,FALSE),0)) -> - | G15: =IF(IFERROR(VLOOKUP(C15,FA_2026!$F$10:$AT$65451,10,FALSE),0)=0,"-",IFERROR(VLOOKUP(C15,FA_2026!$F$10:$AT$65451,10,FALSE),0)) -> 7FBR18-52585 | H15: =IF(IFERROR(VLOOKUP(C15,FA_2026!$F$10:$AT$65451,11,FALSE),0)=0,"-",IFERROR(VLOOKUP(C15,FA_2026!$F$10:$AT$65451,11,FALSE),0)) -> RC22430 | I15: =IFERROR(INDEX(FA_2026!$B$10:$B$1159,MATCH('Disposal 2026'!C15,FA_2026!$F$10:$F$1159,0)),0) -> CLC | J15: =IFERROR(INDEX(FA_2026!$C$10:$C$1159,MATCH('Disposal 2026'!C15,FA_2026!$F$10:$F$1159,0)),0) -> CLCWH | K15: =IF(IFERROR(VLOOKUP(C15,FA_2026!$F$10:$AT$65451,2,FALSE),0)=0,"-",IFERROR(VLOOKUP(C15,FA_2026!$F$10:$AT$65451,2,FALSE),0)) -> 42276 | L15: =IF(IFERROR(VLOOKUP(C15,'List Approval 2025'!$D$7:$M$65624,5,FALSE),0)=0,"-",IFERROR(VLOOKUP(C15,'List Approval 2025'!$D$7:$M$65624,5,FALSE),0)) -> - | M15: =IF(IFERROR(VLOOKUP(C15,FA_2026!$F$10:$AT$65451,14,FALSE),0)=0,"-",IFERROR(VLOOKUP(C15,FA_2026!$F$10:$AT$65451,14,FALSE),0)) -> 229360800 | N15: =IF(IFERROR(VLOOKUP(C15,FA_2026!$F$10:$AT$65451,36,FALSE),0)=0,"-",IFERROR(VLOOKUP(C15,FA_2026!$F$10:$AT$65451,36,FALSE),0)) -> 229360800 | O15: =ROUND(IFERROR(+M15-N15,0),0) -> 0 | P15: =IFERROR(VLOOKUP(C15,'List Approval 2026'!$D$7:$M$276,10,FALSE),0) -> 15765766 | Q15: =(IFERROR(IF(+P15-O15<0,"-",+P15-O15),0)) -> 15765766 | R15: =(IFERROR(IF(P15-O15>=0,"-",O15-P15),0)) -> - | U15: =IFERROR(VLOOKUP(C15,'List Approval 2026'!$D$7:$P$225,13,FALSE),"-") -> Najwa Jaya
